[2017-02-05 06:02:25 +0000] [2658] [INFO] Starting gunicorn 19.6.0
[2017-02-05 06:02:25 +0000] [2658] [INFO] Listening at: http://127.0.0.1:8000 (2658)
[2017-02-05 06:02:25 +0000] [2658] [INFO] Using worker: sync
[2017-02-05 06:02:25 +0000] [2663] [INFO] Booting worker with pid: 2663
[2017-02-05 06:02:25 +0000] [2663] [ERROR] Exception in worker process
Traceback (most recent call last):
  File "/home/ieee/bnbserver/local/lib/python2.7/site-packages/gunicorn/arbiter.py", line 557, in spawn_worker
    worker.init_process()
  File "/home/ieee/bnbserver/local/lib/python2.7/site-packages/gunicorn/workers/base.py", line 126, in init_process
    self.load_wsgi()
  File "/home/ieee/bnbserver/local/lib/python2.7/site-packages/gunicorn/workers/base.py", line 136, in load_wsgi
    self.wsgi = self.app.wsgi()
  File "/home/ieee/bnbserver/local/lib/python2.7/site-packages/gunicorn/app/base.py", line 67, in wsgi
    self.callable = self.load()
  File "/home/ieee/bnbserver/local/lib/python2.7/site-packages/gunicorn/app/wsgiapp.py", line 65, in load
    return self.load_wsgiapp()
  File "/home/ieee/bnbserver/local/lib/python2.7/site-packages/gunicorn/app/wsgiapp.py", line 52, in load_wsgiapp
    return util.import_app(self.app_uri)
  File "/home/ieee/bnbserver/local/lib/python2.7/site-packages/gunicorn/util.py", line 357, in import_app
    __import__(module)
ImportError: No module named wsg
[2017-02-05 06:02:25 +0000] [2663] [INFO] Worker exiting (pid: 2663)
[2017-02-05 06:02:25 +0000] [2658] [INFO] Shutting down: Master
[2017-02-05 06:02:25 +0000] [2658] [INFO] Reason: Worker failed to boot.
[2017-02-05 06:03:58 +0000] [2712] [INFO] Starting gunicorn 19.6.0
[2017-02-05 06:03:58 +0000] [2712] [INFO] Listening at: http://127.0.0.1:8000 (2712)
[2017-02-05 06:03:58 +0000] [2712] [INFO] Using worker: sync
[2017-02-05 06:03:58 +0000] [2717] [INFO] Booting worker with pid: 2717
[2017-02-05 06:04:05 +0000] [2712] [INFO] Handling signal: hup
[2017-02-05 06:04:05 +0000] [2712] [INFO] Hang up: Master
[2017-02-05 06:04:05 +0000] [2722] [INFO] Booting worker with pid: 2722
Internal Server Error: /favicon.ico
Traceback (most recent call last):
  File "/home/ieee/bnbserver/local/lib/python2.7/site-packages/django/core/handlers/exception.py", line 39, in inner
    response = get_response(request)
  File "/home/ieee/bnbserver/local/lib/python2.7/site-packages/django/core/handlers/base.py", line 187, in _get_response
    response = self.process_exception_by_middleware(e, request)
  File "/home/ieee/bnbserver/local/lib/python2.7/site-packages/django/core/handlers/base.py", line 185, in _get_response
    response = wrapped_callback(request, *callback_args, **callback_kwargs)
  File "/home/ieee/bnbserver/local/lib/python2.7/site-packages/django/contrib/auth/decorators.py", line 23, in _wrapped_view
    return view_func(request, *args, **kwargs)
  File "/home/ieee/bnbserver/bnb2017/fblogin/views.py", line 16, in home
    'fbid': SocialAccount.objects.get(user=request.user).uid,
  File "/home/ieee/bnbserver/local/lib/python2.7/site-packages/django/db/models/manager.py", line 85, in manager_method
    return getattr(self.get_queryset(), name)(*args, **kwargs)
  File "/home/ieee/bnbserver/local/lib/python2.7/site-packages/django/db/models/query.py", line 385, in get
    self.model._meta.object_name
DoesNotExist: SocialAccount matching query does not exist.
Internal Server Error: /favicon.ico
Traceback (most recent call last):
  File "/home/ieee/bnbserver/local/lib/python2.7/site-packages/django/core/handlers/exception.py", line 39, in inner
    response = get_response(request)
  File "/home/ieee/bnbserver/local/lib/python2.7/site-packages/django/core/handlers/base.py", line 187, in _get_response
    response = self.process_exception_by_middleware(e, request)
  File "/home/ieee/bnbserver/local/lib/python2.7/site-packages/django/core/handlers/base.py", line 185, in _get_response
    response = wrapped_callback(request, *callback_args, **callback_kwargs)
  File "/home/ieee/bnbserver/local/lib/python2.7/site-packages/django/contrib/auth/decorators.py", line 23, in _wrapped_view
    return view_func(request, *args, **kwargs)
  File "/home/ieee/bnbserver/bnb2017/fblogin/views.py", line 16, in home
    'fbid': SocialAccount.objects.get(user=request.user).uid,
  File "/home/ieee/bnbserver/local/lib/python2.7/site-packages/django/db/models/manager.py", line 85, in manager_method
    return getattr(self.get_queryset(), name)(*args, **kwargs)
  File "/home/ieee/bnbserver/local/lib/python2.7/site-packages/django/db/models/query.py", line 385, in get
    self.model._meta.object_name
DoesNotExist: SocialAccount matching query does not exist.
Internal Server Error: /favicon.ico
Traceback (most recent call last):
  File "/home/ieee/bnbserver/local/lib/python2.7/site-packages/django/core/handlers/exception.py", line 39, in inner
    response = get_response(request)
  File "/home/ieee/bnbserver/local/lib/python2.7/site-packages/django/core/handlers/base.py", line 187, in _get_response
    response = self.process_exception_by_middleware(e, request)
  File "/home/ieee/bnbserver/local/lib/python2.7/site-packages/django/core/handlers/base.py", line 185, in _get_response
    response = wrapped_callback(request, *callback_args, **callback_kwargs)
  File "/home/ieee/bnbserver/local/lib/python2.7/site-packages/django/contrib/auth/decorators.py", line 23, in _wrapped_view
    return view_func(request, *args, **kwargs)
  File "/home/ieee/bnbserver/bnb2017/fblogin/views.py", line 16, in home
    'fbid': SocialAccount.objects.get(user=request.user).uid,
  File "/home/ieee/bnbserver/local/lib/python2.7/site-packages/django/db/models/manager.py", line 85, in manager_method
    return getattr(self.get_queryset(), name)(*args, **kwargs)
  File "/home/ieee/bnbserver/local/lib/python2.7/site-packages/django/db/models/query.py", line 385, in get
    self.model._meta.object_name
DoesNotExist: SocialAccount matching query does not exist.
Internal Server Error: /favicon.ico
Traceback (most recent call last):
  File "/home/ieee/bnbserver/local/lib/python2.7/site-packages/django/core/handlers/exception.py", line 39, in inner
    response = get_response(request)
  File "/home/ieee/bnbserver/local/lib/python2.7/site-packages/django/core/handlers/base.py", line 187, in _get_response
    response = self.process_exception_by_middleware(e, request)
  File "/home/ieee/bnbserver/local/lib/python2.7/site-packages/django/core/handlers/base.py", line 185, in _get_response
    response = wrapped_callback(request, *callback_args, **callback_kwargs)
  File "/home/ieee/bnbserver/local/lib/python2.7/site-packages/django/contrib/auth/decorators.py", line 23, in _wrapped_view
    return view_func(request, *args, **kwargs)
  File "/home/ieee/bnbserver/bnb2017/fblogin/views.py", line 16, in home
    'fbid': SocialAccount.objects.get(user=request.user).uid,
  File "/home/ieee/bnbserver/local/lib/python2.7/site-packages/django/db/models/manager.py", line 85, in manager_method
    return getattr(self.get_queryset(), name)(*args, **kwargs)
  File "/home/ieee/bnbserver/local/lib/python2.7/site-packages/django/db/models/query.py", line 385, in get
    self.model._meta.object_name
DoesNotExist: SocialAccount matching query does not exist.
Internal Server Error: /favicon.ico
Traceback (most recent call last):
  File "/home/ieee/bnbserver/local/lib/python2.7/site-packages/django/core/handlers/exception.py", line 39, in inner
    response = get_response(request)
  File "/home/ieee/bnbserver/local/lib/python2.7/site-packages/django/core/handlers/base.py", line 187, in _get_response
    response = self.process_exception_by_middleware(e, request)
  File "/home/ieee/bnbserver/local/lib/python2.7/site-packages/django/core/handlers/base.py", line 185, in _get_response
    response = wrapped_callback(request, *callback_args, **callback_kwargs)
  File "/home/ieee/bnbserver/local/lib/python2.7/site-packages/django/contrib/auth/decorators.py", line 23, in _wrapped_view
    return view_func(request, *args, **kwargs)
  File "/home/ieee/bnbserver/bnb2017/fblogin/views.py", line 16, in home
    'fbid': SocialAccount.objects.get(user=request.user).uid,
  File "/home/ieee/bnbserver/local/lib/python2.7/site-packages/django/db/models/manager.py", line 85, in manager_method
    return getattr(self.get_queryset(), name)(*args, **kwargs)
  File "/home/ieee/bnbserver/local/lib/python2.7/site-packages/django/db/models/query.py", line 385, in get
    self.model._meta.object_name
DoesNotExist: SocialAccount matching query does not exist.
Internal Server Error: /favicon.ico
Traceback (most recent call last):
  File "/home/ieee/bnbserver/local/lib/python2.7/site-packages/django/core/handlers/exception.py", line 39, in inner
    response = get_response(request)
  File "/home/ieee/bnbserver/local/lib/python2.7/site-packages/django/core/handlers/base.py", line 187, in _get_response
    response = self.process_exception_by_middleware(e, request)
  File "/home/ieee/bnbserver/local/lib/python2.7/site-packages/django/core/handlers/base.py", line 185, in _get_response
    response = wrapped_callback(request, *callback_args, **callback_kwargs)
  File "/home/ieee/bnbserver/local/lib/python2.7/site-packages/django/contrib/auth/decorators.py", line 23, in _wrapped_view
    return view_func(request, *args, **kwargs)
  File "/home/ieee/bnbserver/bnb2017/fblogin/views.py", line 16, in home
    'fbid': SocialAccount.objects.get(user=request.user).uid,
  File "/home/ieee/bnbserver/local/lib/python2.7/site-packages/django/db/models/manager.py", line 85, in manager_method
    return getattr(self.get_queryset(), name)(*args, **kwargs)
  File "/home/ieee/bnbserver/local/lib/python2.7/site-packages/django/db/models/query.py", line 385, in get
    self.model._meta.object_name
DoesNotExist: SocialAccount matching query does not exist.
Internal Server Error: /favicon.ico
Traceback (most recent call last):
  File "/home/ieee/bnbserver/local/lib/python2.7/site-packages/django/core/handlers/exception.py", line 39, in inner
    response = get_response(request)
  File "/home/ieee/bnbserver/local/lib/python2.7/site-packages/django/core/handlers/base.py", line 187, in _get_response
    response = self.process_exception_by_middleware(e, request)
  File "/home/ieee/bnbserver/local/lib/python2.7/site-packages/django/core/handlers/base.py", line 185, in _get_response
    response = wrapped_callback(request, *callback_args, **callback_kwargs)
  File "/home/ieee/bnbserver/local/lib/python2.7/site-packages/django/contrib/auth/decorators.py", line 23, in _wrapped_view
    return view_func(request, *args, **kwargs)
  File "/home/ieee/bnbserver/bnb2017/fblogin/views.py", line 16, in home
    'fbid': SocialAccount.objects.get(user=request.user).uid,
  File "/home/ieee/bnbserver/local/lib/python2.7/site-packages/django/db/models/manager.py", line 85, in manager_method
    return getattr(self.get_queryset(), name)(*args, **kwargs)
  File "/home/ieee/bnbserver/local/lib/python2.7/site-packages/django/db/models/query.py", line 385, in get
    self.model._meta.object_name
DoesNotExist: SocialAccount matching query does not exist.
Internal Server Error: /favicon.ico
Traceback (most recent call last):
  File "/home/ieee/bnbserver/local/lib/python2.7/site-packages/django/core/handlers/exception.py", line 39, in inner
    response = get_response(request)
  File "/home/ieee/bnbserver/local/lib/python2.7/site-packages/django/core/handlers/base.py", line 187, in _get_response
    response = self.process_exception_by_middleware(e, request)
  File "/home/ieee/bnbserver/local/lib/python2.7/site-packages/django/core/handlers/base.py", line 185, in _get_response
    response = wrapped_callback(request, *callback_args, **callback_kwargs)
  File "/home/ieee/bnbserver/local/lib/python2.7/site-packages/django/contrib/auth/decorators.py", line 23, in _wrapped_view
    return view_func(request, *args, **kwargs)
  File "/home/ieee/bnbserver/bnb2017/fblogin/views.py", line 16, in home
    'fbid': SocialAccount.objects.get(user=request.user).uid,
  File "/home/ieee/bnbserver/local/lib/python2.7/site-packages/django/db/models/manager.py", line 85, in manager_method
    return getattr(self.get_queryset(), name)(*args, **kwargs)
  File "/home/ieee/bnbserver/local/lib/python2.7/site-packages/django/db/models/query.py", line 385, in get
    self.model._meta.object_name
DoesNotExist: SocialAccount matching query does not exist.
Internal Server Error: /favicon.ico
Traceback (most recent call last):
  File "/home/ieee/bnbserver/local/lib/python2.7/site-packages/django/core/handlers/exception.py", line 39, in inner
    response = get_response(request)
  File "/home/ieee/bnbserver/local/lib/python2.7/site-packages/django/core/handlers/base.py", line 187, in _get_response
    response = self.process_exception_by_middleware(e, request)
  File "/home/ieee/bnbserver/local/lib/python2.7/site-packages/django/core/handlers/base.py", line 185, in _get_response
    response = wrapped_callback(request, *callback_args, **callback_kwargs)
  File "/home/ieee/bnbserver/local/lib/python2.7/site-packages/django/contrib/auth/decorators.py", line 23, in _wrapped_view
    return view_func(request, *args, **kwargs)
  File "/home/ieee/bnbserver/bnb2017/fblogin/views.py", line 16, in home
    'fbid': SocialAccount.objects.get(user=request.user).uid,
  File "/home/ieee/bnbserver/local/lib/python2.7/site-packages/django/db/models/manager.py", line 85, in manager_method
    return getattr(self.get_queryset(), name)(*args, **kwargs)
  File "/home/ieee/bnbserver/local/lib/python2.7/site-packages/django/db/models/query.py", line 385, in get
    self.model._meta.object_name
DoesNotExist: SocialAccount matching query does not exist.
Internal Server Error: /favicon.ico
Traceback (most recent call last):
  File "/home/ieee/bnbserver/local/lib/python2.7/site-packages/django/core/handlers/exception.py", line 39, in inner
    response = get_response(request)
  File "/home/ieee/bnbserver/local/lib/python2.7/site-packages/django/core/handlers/base.py", line 187, in _get_response
    response = self.process_exception_by_middleware(e, request)
  File "/home/ieee/bnbserver/local/lib/python2.7/site-packages/django/core/handlers/base.py", line 185, in _get_response
    response = wrapped_callback(request, *callback_args, **callback_kwargs)
  File "/home/ieee/bnbserver/local/lib/python2.7/site-packages/django/contrib/auth/decorators.py", line 23, in _wrapped_view
    return view_func(request, *args, **kwargs)
  File "/home/ieee/bnbserver/bnb2017/fblogin/views.py", line 16, in home
    'fbid': SocialAccount.objects.get(user=request.user).uid,
  File "/home/ieee/bnbserver/local/lib/python2.7/site-packages/django/db/models/manager.py", line 85, in manager_method
    return getattr(self.get_queryset(), name)(*args, **kwargs)
  File "/home/ieee/bnbserver/local/lib/python2.7/site-packages/django/db/models/query.py", line 385, in get
    self.model._meta.object_name
DoesNotExist: SocialAccount matching query does not exist.
Internal Server Error: /favicon.ico
Traceback (most recent call last):
  File "/home/ieee/bnbserver/local/lib/python2.7/site-packages/django/core/handlers/exception.py", line 39, in inner
    response = get_response(request)
  File "/home/ieee/bnbserver/local/lib/python2.7/site-packages/django/core/handlers/base.py", line 187, in _get_response
    response = self.process_exception_by_middleware(e, request)
  File "/home/ieee/bnbserver/local/lib/python2.7/site-packages/django/core/handlers/base.py", line 185, in _get_response
    response = wrapped_callback(request, *callback_args, **callback_kwargs)
  File "/home/ieee/bnbserver/local/lib/python2.7/site-packages/django/contrib/auth/decorators.py", line 23, in _wrapped_view
    return view_func(request, *args, **kwargs)
  File "/home/ieee/bnbserver/bnb2017/fblogin/views.py", line 16, in home
    'fbid': SocialAccount.objects.get(user=request.user).uid,
  File "/home/ieee/bnbserver/local/lib/python2.7/site-packages/django/db/models/manager.py", line 85, in manager_method
    return getattr(self.get_queryset(), name)(*args, **kwargs)
  File "/home/ieee/bnbserver/local/lib/python2.7/site-packages/django/db/models/query.py", line 385, in get
    self.model._meta.object_name
DoesNotExist: SocialAccount matching query does not exist.
Internal Server Error: /favicon.ico
Traceback (most recent call last):
  File "/home/ieee/bnbserver/local/lib/python2.7/site-packages/django/core/handlers/exception.py", line 39, in inner
    response = get_response(request)
  File "/home/ieee/bnbserver/local/lib/python2.7/site-packages/django/core/handlers/base.py", line 187, in _get_response
    response = self.process_exception_by_middleware(e, request)
  File "/home/ieee/bnbserver/local/lib/python2.7/site-packages/django/core/handlers/base.py", line 185, in _get_response
    response = wrapped_callback(request, *callback_args, **callback_kwargs)
  File "/home/ieee/bnbserver/local/lib/python2.7/site-packages/django/contrib/auth/decorators.py", line 23, in _wrapped_view
    return view_func(request, *args, **kwargs)
  File "/home/ieee/bnbserver/bnb2017/fblogin/views.py", line 16, in home
    'fbid': SocialAccount.objects.get(user=request.user).uid,
  File "/home/ieee/bnbserver/local/lib/python2.7/site-packages/django/db/models/manager.py", line 85, in manager_method
    return getattr(self.get_queryset(), name)(*args, **kwargs)
  File "/home/ieee/bnbserver/local/lib/python2.7/site-packages/django/db/models/query.py", line 385, in get
    self.model._meta.object_name
DoesNotExist: SocialAccount matching query does not exist.
Internal Server Error: /favicon.ico
Traceback (most recent call last):
  File "/home/ieee/bnbserver/local/lib/python2.7/site-packages/django/core/handlers/exception.py", line 39, in inner
    response = get_response(request)
  File "/home/ieee/bnbserver/local/lib/python2.7/site-packages/django/core/handlers/base.py", line 187, in _get_response
    response = self.process_exception_by_middleware(e, request)
  File "/home/ieee/bnbserver/local/lib/python2.7/site-packages/django/core/handlers/base.py", line 185, in _get_response
    response = wrapped_callback(request, *callback_args, **callback_kwargs)
  File "/home/ieee/bnbserver/local/lib/python2.7/site-packages/django/contrib/auth/decorators.py", line 23, in _wrapped_view
    return view_func(request, *args, **kwargs)
  File "/home/ieee/bnbserver/bnb2017/fblogin/views.py", line 16, in home
    'fbid': SocialAccount.objects.get(user=request.user).uid,
  File "/home/ieee/bnbserver/local/lib/python2.7/site-packages/django/db/models/manager.py", line 85, in manager_method
    return getattr(self.get_queryset(), name)(*args, **kwargs)
  File "/home/ieee/bnbserver/local/lib/python2.7/site-packages/django/db/models/query.py", line 385, in get
    self.model._meta.object_name
DoesNotExist: SocialAccount matching query does not exist.
Internal Server Error: /favicon.ico
Traceback (most recent call last):
  File "/home/ieee/bnbserver/local/lib/python2.7/site-packages/django/core/handlers/exception.py", line 39, in inner
    response = get_response(request)
  File "/home/ieee/bnbserver/local/lib/python2.7/site-packages/django/core/handlers/base.py", line 187, in _get_response
    response = self.process_exception_by_middleware(e, request)
  File "/home/ieee/bnbserver/local/lib/python2.7/site-packages/django/core/handlers/base.py", line 185, in _get_response
    response = wrapped_callback(request, *callback_args, **callback_kwargs)
  File "/home/ieee/bnbserver/local/lib/python2.7/site-packages/django/contrib/auth/decorators.py", line 23, in _wrapped_view
    return view_func(request, *args, **kwargs)
  File "/home/ieee/bnbserver/bnb2017/fblogin/views.py", line 16, in home
    'fbid': SocialAccount.objects.get(user=request.user).uid,
  File "/home/ieee/bnbserver/local/lib/python2.7/site-packages/django/db/models/manager.py", line 85, in manager_method
    return getattr(self.get_queryset(), name)(*args, **kwargs)
  File "/home/ieee/bnbserver/local/lib/python2.7/site-packages/django/db/models/query.py", line 385, in get
    self.model._meta.object_name
DoesNotExist: SocialAccount matching query does not exist.
Internal Server Error: /favicon.ico
Traceback (most recent call last):
  File "/home/ieee/bnbserver/local/lib/python2.7/site-packages/django/core/handlers/exception.py", line 39, in inner
    response = get_response(request)
  File "/home/ieee/bnbserver/local/lib/python2.7/site-packages/django/core/handlers/base.py", line 187, in _get_response
    response = self.process_exception_by_middleware(e, request)
  File "/home/ieee/bnbserver/local/lib/python2.7/site-packages/django/core/handlers/base.py", line 185, in _get_response
    response = wrapped_callback(request, *callback_args, **callback_kwargs)
  File "/home/ieee/bnbserver/local/lib/python2.7/site-packages/django/contrib/auth/decorators.py", line 23, in _wrapped_view
    return view_func(request, *args, **kwargs)
  File "/home/ieee/bnbserver/bnb2017/fblogin/views.py", line 16, in home
    'fbid': SocialAccount.objects.get(user=request.user).uid,
  File "/home/ieee/bnbserver/local/lib/python2.7/site-packages/django/db/models/manager.py", line 85, in manager_method
    return getattr(self.get_queryset(), name)(*args, **kwargs)
  File "/home/ieee/bnbserver/local/lib/python2.7/site-packages/django/db/models/query.py", line 385, in get
    self.model._meta.object_name
DoesNotExist: SocialAccount matching query does not exist.
Internal Server Error: /favicon.ico
Traceback (most recent call last):
  File "/home/ieee/bnbserver/local/lib/python2.7/site-packages/django/core/handlers/exception.py", line 39, in inner
    response = get_response(request)
  File "/home/ieee/bnbserver/local/lib/python2.7/site-packages/django/core/handlers/base.py", line 187, in _get_response
    response = self.process_exception_by_middleware(e, request)
  File "/home/ieee/bnbserver/local/lib/python2.7/site-packages/django/core/handlers/base.py", line 185, in _get_response
    response = wrapped_callback(request, *callback_args, **callback_kwargs)
  File "/home/ieee/bnbserver/local/lib/python2.7/site-packages/django/contrib/auth/decorators.py", line 23, in _wrapped_view
    return view_func(request, *args, **kwargs)
  File "/home/ieee/bnbserver/bnb2017/fblogin/views.py", line 16, in home
    'fbid': SocialAccount.objects.get(user=request.user).uid,
  File "/home/ieee/bnbserver/local/lib/python2.7/site-packages/django/db/models/manager.py", line 85, in manager_method
    return getattr(self.get_queryset(), name)(*args, **kwargs)
  File "/home/ieee/bnbserver/local/lib/python2.7/site-packages/django/db/models/query.py", line 385, in get
    self.model._meta.object_name
DoesNotExist: SocialAccount matching query does not exist.
Internal Server Error: /favicon.ico
Traceback (most recent call last):
  File "/home/ieee/bnbserver/local/lib/python2.7/site-packages/django/core/handlers/exception.py", line 39, in inner
    response = get_response(request)
  File "/home/ieee/bnbserver/local/lib/python2.7/site-packages/django/core/handlers/base.py", line 187, in _get_response
    response = self.process_exception_by_middleware(e, request)
  File "/home/ieee/bnbserver/local/lib/python2.7/site-packages/django/core/handlers/base.py", line 185, in _get_response
    response = wrapped_callback(request, *callback_args, **callback_kwargs)
  File "/home/ieee/bnbserver/local/lib/python2.7/site-packages/django/contrib/auth/decorators.py", line 23, in _wrapped_view
    return view_func(request, *args, **kwargs)
  File "/home/ieee/bnbserver/bnb2017/fblogin/views.py", line 16, in home
    'fbid': SocialAccount.objects.get(user=request.user).uid,
  File "/home/ieee/bnbserver/local/lib/python2.7/site-packages/django/db/models/manager.py", line 85, in manager_method
    return getattr(self.get_queryset(), name)(*args, **kwargs)
  File "/home/ieee/bnbserver/local/lib/python2.7/site-packages/django/db/models/query.py", line 385, in get
    self.model._meta.object_name
DoesNotExist: SocialAccount matching query does not exist.
Internal Server Error: /favicon.ico
Traceback (most recent call last):
  File "/home/ieee/bnbserver/local/lib/python2.7/site-packages/django/core/handlers/exception.py", line 39, in inner
    response = get_response(request)
  File "/home/ieee/bnbserver/local/lib/python2.7/site-packages/django/core/handlers/base.py", line 187, in _get_response
    response = self.process_exception_by_middleware(e, request)
  File "/home/ieee/bnbserver/local/lib/python2.7/site-packages/django/core/handlers/base.py", line 185, in _get_response
    response = wrapped_callback(request, *callback_args, **callback_kwargs)
  File "/home/ieee/bnbserver/local/lib/python2.7/site-packages/django/contrib/auth/decorators.py", line 23, in _wrapped_view
    return view_func(request, *args, **kwargs)
  File "/home/ieee/bnbserver/bnb2017/fblogin/views.py", line 16, in home
    'fbid': SocialAccount.objects.get(user=request.user).uid,
  File "/home/ieee/bnbserver/local/lib/python2.7/site-packages/django/db/models/manager.py", line 85, in manager_method
    return getattr(self.get_queryset(), name)(*args, **kwargs)
  File "/home/ieee/bnbserver/local/lib/python2.7/site-packages/django/db/models/query.py", line 385, in get
    self.model._meta.object_name
DoesNotExist: SocialAccount matching query does not exist.
Internal Server Error: /favicon.ico
Traceback (most recent call last):
  File "/home/ieee/bnbserver/local/lib/python2.7/site-packages/django/core/handlers/exception.py", line 39, in inner
    response = get_response(request)
  File "/home/ieee/bnbserver/local/lib/python2.7/site-packages/django/core/handlers/base.py", line 187, in _get_response
    response = self.process_exception_by_middleware(e, request)
  File "/home/ieee/bnbserver/local/lib/python2.7/site-packages/django/core/handlers/base.py", line 185, in _get_response
    response = wrapped_callback(request, *callback_args, **callback_kwargs)
  File "/home/ieee/bnbserver/local/lib/python2.7/site-packages/django/contrib/auth/decorators.py", line 23, in _wrapped_view
    return view_func(request, *args, **kwargs)
  File "/home/ieee/bnbserver/bnb2017/fblogin/views.py", line 16, in home
    'fbid': SocialAccount.objects.get(user=request.user).uid,
  File "/home/ieee/bnbserver/local/lib/python2.7/site-packages/django/db/models/manager.py", line 85, in manager_method
    return getattr(self.get_queryset(), name)(*args, **kwargs)
  File "/home/ieee/bnbserver/local/lib/python2.7/site-packages/django/db/models/query.py", line 385, in get
    self.model._meta.object_name
DoesNotExist: SocialAccount matching query does not exist.
Internal Server Error: /favicon.ico
Traceback (most recent call last):
  File "/home/ieee/bnbserver/local/lib/python2.7/site-packages/django/core/handlers/exception.py", line 39, in inner
    response = get_response(request)
  File "/home/ieee/bnbserver/local/lib/python2.7/site-packages/django/core/handlers/base.py", line 187, in _get_response
    response = self.process_exception_by_middleware(e, request)
  File "/home/ieee/bnbserver/local/lib/python2.7/site-packages/django/core/handlers/base.py", line 185, in _get_response
    response = wrapped_callback(request, *callback_args, **callback_kwargs)
  File "/home/ieee/bnbserver/local/lib/python2.7/site-packages/django/contrib/auth/decorators.py", line 23, in _wrapped_view
    return view_func(request, *args, **kwargs)
  File "/home/ieee/bnbserver/bnb2017/fblogin/views.py", line 16, in home
    'fbid': SocialAccount.objects.get(user=request.user).uid,
  File "/home/ieee/bnbserver/local/lib/python2.7/site-packages/django/db/models/manager.py", line 85, in manager_method
    return getattr(self.get_queryset(), name)(*args, **kwargs)
  File "/home/ieee/bnbserver/local/lib/python2.7/site-packages/django/db/models/query.py", line 385, in get
    self.model._meta.object_name
DoesNotExist: SocialAccount matching query does not exist.
Internal Server Error: /favicon.ico
Traceback (most recent call last):
  File "/home/ieee/bnbserver/local/lib/python2.7/site-packages/django/core/handlers/exception.py", line 39, in inner
    response = get_response(request)
  File "/home/ieee/bnbserver/local/lib/python2.7/site-packages/django/core/handlers/base.py", line 187, in _get_response
    response = self.process_exception_by_middleware(e, request)
  File "/home/ieee/bnbserver/local/lib/python2.7/site-packages/django/core/handlers/base.py", line 185, in _get_response
    response = wrapped_callback(request, *callback_args, **callback_kwargs)
  File "/home/ieee/bnbserver/local/lib/python2.7/site-packages/django/contrib/auth/decorators.py", line 23, in _wrapped_view
    return view_func(request, *args, **kwargs)
  File "/home/ieee/bnbserver/bnb2017/fblogin/views.py", line 16, in home
    'fbid': SocialAccount.objects.get(user=request.user).uid,
  File "/home/ieee/bnbserver/local/lib/python2.7/site-packages/django/db/models/manager.py", line 85, in manager_method
    return getattr(self.get_queryset(), name)(*args, **kwargs)
  File "/home/ieee/bnbserver/local/lib/python2.7/site-packages/django/db/models/query.py", line 385, in get
    self.model._meta.object_name
DoesNotExist: SocialAccount matching query does not exist.
Internal Server Error: /favicon.ico
Traceback (most recent call last):
  File "/home/ieee/bnbserver/local/lib/python2.7/site-packages/django/core/handlers/exception.py", line 39, in inner
    response = get_response(request)
  File "/home/ieee/bnbserver/local/lib/python2.7/site-packages/django/core/handlers/base.py", line 187, in _get_response
    response = self.process_exception_by_middleware(e, request)
  File "/home/ieee/bnbserver/local/lib/python2.7/site-packages/django/core/handlers/base.py", line 185, in _get_response
    response = wrapped_callback(request, *callback_args, **callback_kwargs)
  File "/home/ieee/bnbserver/local/lib/python2.7/site-packages/django/contrib/auth/decorators.py", line 23, in _wrapped_view
    return view_func(request, *args, **kwargs)
  File "/home/ieee/bnbserver/bnb2017/fblogin/views.py", line 16, in home
    'fbid': SocialAccount.objects.get(user=request.user).uid,
  File "/home/ieee/bnbserver/local/lib/python2.7/site-packages/django/db/models/manager.py", line 85, in manager_method
    return getattr(self.get_queryset(), name)(*args, **kwargs)
  File "/home/ieee/bnbserver/local/lib/python2.7/site-packages/django/db/models/query.py", line 385, in get
    self.model._meta.object_name
DoesNotExist: SocialAccount matching query does not exist.
Internal Server Error: /favicon.ico
Traceback (most recent call last):
  File "/home/ieee/bnbserver/local/lib/python2.7/site-packages/django/core/handlers/exception.py", line 39, in inner
    response = get_response(request)
  File "/home/ieee/bnbserver/local/lib/python2.7/site-packages/django/core/handlers/base.py", line 187, in _get_response
    response = self.process_exception_by_middleware(e, request)
  File "/home/ieee/bnbserver/local/lib/python2.7/site-packages/django/core/handlers/base.py", line 185, in _get_response
    response = wrapped_callback(request, *callback_args, **callback_kwargs)
  File "/home/ieee/bnbserver/local/lib/python2.7/site-packages/django/contrib/auth/decorators.py", line 23, in _wrapped_view
    return view_func(request, *args, **kwargs)
  File "/home/ieee/bnbserver/bnb2017/fblogin/views.py", line 16, in home
    'fbid': SocialAccount.objects.get(user=request.user).uid,
  File "/home/ieee/bnbserver/local/lib/python2.7/site-packages/django/db/models/manager.py", line 85, in manager_method
    return getattr(self.get_queryset(), name)(*args, **kwargs)
  File "/home/ieee/bnbserver/local/lib/python2.7/site-packages/django/db/models/query.py", line 385, in get
    self.model._meta.object_name
DoesNotExist: SocialAccount matching query does not exist.
Internal Server Error: /favicon.ico
Traceback (most recent call last):
  File "/home/ieee/bnbserver/local/lib/python2.7/site-packages/django/core/handlers/exception.py", line 39, in inner
    response = get_response(request)
  File "/home/ieee/bnbserver/local/lib/python2.7/site-packages/django/core/handlers/base.py", line 187, in _get_response
    response = self.process_exception_by_middleware(e, request)
  File "/home/ieee/bnbserver/local/lib/python2.7/site-packages/django/core/handlers/base.py", line 185, in _get_response
    response = wrapped_callback(request, *callback_args, **callback_kwargs)
  File "/home/ieee/bnbserver/local/lib/python2.7/site-packages/django/contrib/auth/decorators.py", line 23, in _wrapped_view
    return view_func(request, *args, **kwargs)
  File "/home/ieee/bnbserver/bnb2017/fblogin/views.py", line 16, in home
    'fbid': SocialAccount.objects.get(user=request.user).uid,
  File "/home/ieee/bnbserver/local/lib/python2.7/site-packages/django/db/models/manager.py", line 85, in manager_method
    return getattr(self.get_queryset(), name)(*args, **kwargs)
  File "/home/ieee/bnbserver/local/lib/python2.7/site-packages/django/db/models/query.py", line 385, in get
    self.model._meta.object_name
DoesNotExist: SocialAccount matching query does not exist.
Internal Server Error: /favicon.ico
Traceback (most recent call last):
  File "/home/ieee/bnbserver/local/lib/python2.7/site-packages/django/core/handlers/exception.py", line 39, in inner
    response = get_response(request)
  File "/home/ieee/bnbserver/local/lib/python2.7/site-packages/django/core/handlers/base.py", line 187, in _get_response
    response = self.process_exception_by_middleware(e, request)
  File "/home/ieee/bnbserver/local/lib/python2.7/site-packages/django/core/handlers/base.py", line 185, in _get_response
    response = wrapped_callback(request, *callback_args, **callback_kwargs)
  File "/home/ieee/bnbserver/local/lib/python2.7/site-packages/django/contrib/auth/decorators.py", line 23, in _wrapped_view
    return view_func(request, *args, **kwargs)
  File "/home/ieee/bnbserver/bnb2017/fblogin/views.py", line 16, in home
    'fbid': SocialAccount.objects.get(user=request.user).uid,
  File "/home/ieee/bnbserver/local/lib/python2.7/site-packages/django/db/models/manager.py", line 85, in manager_method
    return getattr(self.get_queryset(), name)(*args, **kwargs)
  File "/home/ieee/bnbserver/local/lib/python2.7/site-packages/django/db/models/query.py", line 385, in get
    self.model._meta.object_name
DoesNotExist: SocialAccount matching query does not exist.
Internal Server Error: /favicon.ico
Traceback (most recent call last):
  File "/home/ieee/bnbserver/local/lib/python2.7/site-packages/django/core/handlers/exception.py", line 39, in inner
    response = get_response(request)
  File "/home/ieee/bnbserver/local/lib/python2.7/site-packages/django/core/handlers/base.py", line 187, in _get_response
    response = self.process_exception_by_middleware(e, request)
  File "/home/ieee/bnbserver/local/lib/python2.7/site-packages/django/core/handlers/base.py", line 185, in _get_response
    response = wrapped_callback(request, *callback_args, **callback_kwargs)
  File "/home/ieee/bnbserver/local/lib/python2.7/site-packages/django/contrib/auth/decorators.py", line 23, in _wrapped_view
    return view_func(request, *args, **kwargs)
  File "/home/ieee/bnbserver/bnb2017/fblogin/views.py", line 16, in home
    'fbid': SocialAccount.objects.get(user=request.user).uid,
  File "/home/ieee/bnbserver/local/lib/python2.7/site-packages/django/db/models/manager.py", line 85, in manager_method
    return getattr(self.get_queryset(), name)(*args, **kwargs)
  File "/home/ieee/bnbserver/local/lib/python2.7/site-packages/django/db/models/query.py", line 385, in get
    self.model._meta.object_name
DoesNotExist: SocialAccount matching query does not exist.
Internal Server Error: /favicon.ico
Traceback (most recent call last):
  File "/home/ieee/bnbserver/local/lib/python2.7/site-packages/django/core/handlers/exception.py", line 39, in inner
    response = get_response(request)
  File "/home/ieee/bnbserver/local/lib/python2.7/site-packages/django/core/handlers/base.py", line 187, in _get_response
    response = self.process_exception_by_middleware(e, request)
  File "/home/ieee/bnbserver/local/lib/python2.7/site-packages/django/core/handlers/base.py", line 185, in _get_response
    response = wrapped_callback(request, *callback_args, **callback_kwargs)
  File "/home/ieee/bnbserver/local/lib/python2.7/site-packages/django/contrib/auth/decorators.py", line 23, in _wrapped_view
    return view_func(request, *args, **kwargs)
  File "/home/ieee/bnbserver/bnb2017/fblogin/views.py", line 16, in home
    'fbid': SocialAccount.objects.get(user=request.user).uid,
  File "/home/ieee/bnbserver/local/lib/python2.7/site-packages/django/db/models/manager.py", line 85, in manager_method
    return getattr(self.get_queryset(), name)(*args, **kwargs)
  File "/home/ieee/bnbserver/local/lib/python2.7/site-packages/django/db/models/query.py", line 385, in get
    self.model._meta.object_name
DoesNotExist: SocialAccount matching query does not exist.
Internal Server Error: /favicon.ico
Traceback (most recent call last):
  File "/home/ieee/bnbserver/local/lib/python2.7/site-packages/django/core/handlers/exception.py", line 39, in inner
    response = get_response(request)
  File "/home/ieee/bnbserver/local/lib/python2.7/site-packages/django/core/handlers/base.py", line 187, in _get_response
    response = self.process_exception_by_middleware(e, request)
  File "/home/ieee/bnbserver/local/lib/python2.7/site-packages/django/core/handlers/base.py", line 185, in _get_response
    response = wrapped_callback(request, *callback_args, **callback_kwargs)
  File "/home/ieee/bnbserver/local/lib/python2.7/site-packages/django/contrib/auth/decorators.py", line 23, in _wrapped_view
    return view_func(request, *args, **kwargs)
  File "/home/ieee/bnbserver/bnb2017/fblogin/views.py", line 16, in home
    'fbid': SocialAccount.objects.get(user=request.user).uid,
  File "/home/ieee/bnbserver/local/lib/python2.7/site-packages/django/db/models/manager.py", line 85, in manager_method
    return getattr(self.get_queryset(), name)(*args, **kwargs)
  File "/home/ieee/bnbserver/local/lib/python2.7/site-packages/django/db/models/query.py", line 385, in get
    self.model._meta.object_name
DoesNotExist: SocialAccount matching query does not exist.
Internal Server Error: /favicon.ico
Traceback (most recent call last):
  File "/home/ieee/bnbserver/local/lib/python2.7/site-packages/django/core/handlers/exception.py", line 39, in inner
    response = get_response(request)
  File "/home/ieee/bnbserver/local/lib/python2.7/site-packages/django/core/handlers/base.py", line 187, in _get_response
    response = self.process_exception_by_middleware(e, request)
  File "/home/ieee/bnbserver/local/lib/python2.7/site-packages/django/core/handlers/base.py", line 185, in _get_response
    response = wrapped_callback(request, *callback_args, **callback_kwargs)
  File "/home/ieee/bnbserver/local/lib/python2.7/site-packages/django/contrib/auth/decorators.py", line 23, in _wrapped_view
    return view_func(request, *args, **kwargs)
  File "/home/ieee/bnbserver/bnb2017/fblogin/views.py", line 16, in home
    'fbid': SocialAccount.objects.get(user=request.user).uid,
  File "/home/ieee/bnbserver/local/lib/python2.7/site-packages/django/db/models/manager.py", line 85, in manager_method
    return getattr(self.get_queryset(), name)(*args, **kwargs)
  File "/home/ieee/bnbserver/local/lib/python2.7/site-packages/django/db/models/query.py", line 385, in get
    self.model._meta.object_name
DoesNotExist: SocialAccount matching query does not exist.
Internal Server Error: /favicon.ico
Traceback (most recent call last):
  File "/home/ieee/bnbserver/local/lib/python2.7/site-packages/django/core/handlers/exception.py", line 39, in inner
    response = get_response(request)
  File "/home/ieee/bnbserver/local/lib/python2.7/site-packages/django/core/handlers/base.py", line 187, in _get_response
    response = self.process_exception_by_middleware(e, request)
  File "/home/ieee/bnbserver/local/lib/python2.7/site-packages/django/core/handlers/base.py", line 185, in _get_response
    response = wrapped_callback(request, *callback_args, **callback_kwargs)
  File "/home/ieee/bnbserver/local/lib/python2.7/site-packages/django/contrib/auth/decorators.py", line 23, in _wrapped_view
    return view_func(request, *args, **kwargs)
  File "/home/ieee/bnbserver/bnb2017/fblogin/views.py", line 16, in home
    'fbid': SocialAccount.objects.get(user=request.user).uid,
  File "/home/ieee/bnbserver/local/lib/python2.7/site-packages/django/db/models/manager.py", line 85, in manager_method
    return getattr(self.get_queryset(), name)(*args, **kwargs)
  File "/home/ieee/bnbserver/local/lib/python2.7/site-packages/django/db/models/query.py", line 385, in get
    self.model._meta.object_name
DoesNotExist: SocialAccount matching query does not exist.
Internal Server Error: /favicon.ico
Traceback (most recent call last):
  File "/home/ieee/bnbserver/local/lib/python2.7/site-packages/django/core/handlers/exception.py", line 39, in inner
    response = get_response(request)
  File "/home/ieee/bnbserver/local/lib/python2.7/site-packages/django/core/handlers/base.py", line 187, in _get_response
    response = self.process_exception_by_middleware(e, request)
  File "/home/ieee/bnbserver/local/lib/python2.7/site-packages/django/core/handlers/base.py", line 185, in _get_response
    response = wrapped_callback(request, *callback_args, **callback_kwargs)
  File "/home/ieee/bnbserver/local/lib/python2.7/site-packages/django/contrib/auth/decorators.py", line 23, in _wrapped_view
    return view_func(request, *args, **kwargs)
  File "/home/ieee/bnbserver/bnb2017/fblogin/views.py", line 16, in home
    'fbid': SocialAccount.objects.get(user=request.user).uid,
  File "/home/ieee/bnbserver/local/lib/python2.7/site-packages/django/db/models/manager.py", line 85, in manager_method
    return getattr(self.get_queryset(), name)(*args, **kwargs)
  File "/home/ieee/bnbserver/local/lib/python2.7/site-packages/django/db/models/query.py", line 385, in get
    self.model._meta.object_name
DoesNotExist: SocialAccount matching query does not exist.
Internal Server Error: /favicon.ico
Traceback (most recent call last):
  File "/home/ieee/bnbserver/local/lib/python2.7/site-packages/django/core/handlers/exception.py", line 39, in inner
    response = get_response(request)
  File "/home/ieee/bnbserver/local/lib/python2.7/site-packages/django/core/handlers/base.py", line 187, in _get_response
    response = self.process_exception_by_middleware(e, request)
  File "/home/ieee/bnbserver/local/lib/python2.7/site-packages/django/core/handlers/base.py", line 185, in _get_response
    response = wrapped_callback(request, *callback_args, **callback_kwargs)
  File "/home/ieee/bnbserver/local/lib/python2.7/site-packages/django/contrib/auth/decorators.py", line 23, in _wrapped_view
    return view_func(request, *args, **kwargs)
  File "/home/ieee/bnbserver/bnb2017/fblogin/views.py", line 16, in home
    'fbid': SocialAccount.objects.get(user=request.user).uid,
  File "/home/ieee/bnbserver/local/lib/python2.7/site-packages/django/db/models/manager.py", line 85, in manager_method
    return getattr(self.get_queryset(), name)(*args, **kwargs)
  File "/home/ieee/bnbserver/local/lib/python2.7/site-packages/django/db/models/query.py", line 385, in get
    self.model._meta.object_name
DoesNotExist: SocialAccount matching query does not exist.
Internal Server Error: /favicon.ico
Traceback (most recent call last):
  File "/home/ieee/bnbserver/local/lib/python2.7/site-packages/django/core/handlers/exception.py", line 39, in inner
    response = get_response(request)
  File "/home/ieee/bnbserver/local/lib/python2.7/site-packages/django/core/handlers/base.py", line 187, in _get_response
    response = self.process_exception_by_middleware(e, request)
  File "/home/ieee/bnbserver/local/lib/python2.7/site-packages/django/core/handlers/base.py", line 185, in _get_response
    response = wrapped_callback(request, *callback_args, **callback_kwargs)
  File "/home/ieee/bnbserver/local/lib/python2.7/site-packages/django/contrib/auth/decorators.py", line 23, in _wrapped_view
    return view_func(request, *args, **kwargs)
  File "/home/ieee/bnbserver/bnb2017/fblogin/views.py", line 16, in home
    'fbid': SocialAccount.objects.get(user=request.user).uid,
  File "/home/ieee/bnbserver/local/lib/python2.7/site-packages/django/db/models/manager.py", line 85, in manager_method
    return getattr(self.get_queryset(), name)(*args, **kwargs)
  File "/home/ieee/bnbserver/local/lib/python2.7/site-packages/django/db/models/query.py", line 385, in get
    self.model._meta.object_name
DoesNotExist: SocialAccount matching query does not exist.
Internal Server Error: /favicon.ico
Traceback (most recent call last):
  File "/home/ieee/bnbserver/local/lib/python2.7/site-packages/django/core/handlers/exception.py", line 39, in inner
    response = get_response(request)
  File "/home/ieee/bnbserver/local/lib/python2.7/site-packages/django/core/handlers/base.py", line 187, in _get_response
    response = self.process_exception_by_middleware(e, request)
  File "/home/ieee/bnbserver/local/lib/python2.7/site-packages/django/core/handlers/base.py", line 185, in _get_response
    response = wrapped_callback(request, *callback_args, **callback_kwargs)
  File "/home/ieee/bnbserver/local/lib/python2.7/site-packages/django/contrib/auth/decorators.py", line 23, in _wrapped_view
    return view_func(request, *args, **kwargs)
  File "/home/ieee/bnbserver/bnb2017/fblogin/views.py", line 16, in home
    'fbid': SocialAccount.objects.get(user=request.user).uid,
  File "/home/ieee/bnbserver/local/lib/python2.7/site-packages/django/db/models/manager.py", line 85, in manager_method
    return getattr(self.get_queryset(), name)(*args, **kwargs)
  File "/home/ieee/bnbserver/local/lib/python2.7/site-packages/django/db/models/query.py", line 385, in get
    self.model._meta.object_name
DoesNotExist: SocialAccount matching query does not exist.
Internal Server Error: /favicon.ico
Traceback (most recent call last):
  File "/home/ieee/bnbserver/local/lib/python2.7/site-packages/django/core/handlers/exception.py", line 39, in inner
    response = get_response(request)
  File "/home/ieee/bnbserver/local/lib/python2.7/site-packages/django/core/handlers/base.py", line 187, in _get_response
    response = self.process_exception_by_middleware(e, request)
  File "/home/ieee/bnbserver/local/lib/python2.7/site-packages/django/core/handlers/base.py", line 185, in _get_response
    response = wrapped_callback(request, *callback_args, **callback_kwargs)
  File "/home/ieee/bnbserver/local/lib/python2.7/site-packages/django/contrib/auth/decorators.py", line 23, in _wrapped_view
    return view_func(request, *args, **kwargs)
  File "/home/ieee/bnbserver/bnb2017/fblogin/views.py", line 16, in home
    'fbid': SocialAccount.objects.get(user=request.user).uid,
  File "/home/ieee/bnbserver/local/lib/python2.7/site-packages/django/db/models/manager.py", line 85, in manager_method
    return getattr(self.get_queryset(), name)(*args, **kwargs)
  File "/home/ieee/bnbserver/local/lib/python2.7/site-packages/django/db/models/query.py", line 385, in get
    self.model._meta.object_name
DoesNotExist: SocialAccount matching query does not exist.
Internal Server Error: /favicon.ico
Traceback (most recent call last):
  File "/home/ieee/bnbserver/local/lib/python2.7/site-packages/django/core/handlers/exception.py", line 39, in inner
    response = get_response(request)
  File "/home/ieee/bnbserver/local/lib/python2.7/site-packages/django/core/handlers/base.py", line 187, in _get_response
    response = self.process_exception_by_middleware(e, request)
  File "/home/ieee/bnbserver/local/lib/python2.7/site-packages/django/core/handlers/base.py", line 185, in _get_response
    response = wrapped_callback(request, *callback_args, **callback_kwargs)
  File "/home/ieee/bnbserver/local/lib/python2.7/site-packages/django/contrib/auth/decorators.py", line 23, in _wrapped_view
    return view_func(request, *args, **kwargs)
  File "/home/ieee/bnbserver/bnb2017/fblogin/views.py", line 16, in home
    'fbid': SocialAccount.objects.get(user=request.user).uid,
  File "/home/ieee/bnbserver/local/lib/python2.7/site-packages/django/db/models/manager.py", line 85, in manager_method
    return getattr(self.get_queryset(), name)(*args, **kwargs)
  File "/home/ieee/bnbserver/local/lib/python2.7/site-packages/django/db/models/query.py", line 385, in get
    self.model._meta.object_name
DoesNotExist: SocialAccount matching query does not exist.
Internal Server Error: /favicon.ico
Traceback (most recent call last):
  File "/home/ieee/bnbserver/local/lib/python2.7/site-packages/django/core/handlers/exception.py", line 39, in inner
    response = get_response(request)
  File "/home/ieee/bnbserver/local/lib/python2.7/site-packages/django/core/handlers/base.py", line 187, in _get_response
    response = self.process_exception_by_middleware(e, request)
  File "/home/ieee/bnbserver/local/lib/python2.7/site-packages/django/core/handlers/base.py", line 185, in _get_response
    response = wrapped_callback(request, *callback_args, **callback_kwargs)
  File "/home/ieee/bnbserver/local/lib/python2.7/site-packages/django/contrib/auth/decorators.py", line 23, in _wrapped_view
    return view_func(request, *args, **kwargs)
  File "/home/ieee/bnbserver/bnb2017/fblogin/views.py", line 16, in home
    'fbid': SocialAccount.objects.get(user=request.user).uid,
  File "/home/ieee/bnbserver/local/lib/python2.7/site-packages/django/db/models/manager.py", line 85, in manager_method
    return getattr(self.get_queryset(), name)(*args, **kwargs)
  File "/home/ieee/bnbserver/local/lib/python2.7/site-packages/django/db/models/query.py", line 385, in get
    self.model._meta.object_name
DoesNotExist: SocialAccount matching query does not exist.
Internal Server Error: /favicon.ico
Traceback (most recent call last):
  File "/home/ieee/bnbserver/local/lib/python2.7/site-packages/django/core/handlers/exception.py", line 39, in inner
    response = get_response(request)
  File "/home/ieee/bnbserver/local/lib/python2.7/site-packages/django/core/handlers/base.py", line 187, in _get_response
    response = self.process_exception_by_middleware(e, request)
  File "/home/ieee/bnbserver/local/lib/python2.7/site-packages/django/core/handlers/base.py", line 185, in _get_response
    response = wrapped_callback(request, *callback_args, **callback_kwargs)
  File "/home/ieee/bnbserver/local/lib/python2.7/site-packages/django/contrib/auth/decorators.py", line 23, in _wrapped_view
    return view_func(request, *args, **kwargs)
  File "/home/ieee/bnbserver/bnb2017/fblogin/views.py", line 16, in home
    'fbid': SocialAccount.objects.get(user=request.user).uid,
  File "/home/ieee/bnbserver/local/lib/python2.7/site-packages/django/db/models/manager.py", line 85, in manager_method
    return getattr(self.get_queryset(), name)(*args, **kwargs)
  File "/home/ieee/bnbserver/local/lib/python2.7/site-packages/django/db/models/query.py", line 385, in get
    self.model._meta.object_name
DoesNotExist: SocialAccount matching query does not exist.
Internal Server Error: /favicon.ico
Traceback (most recent call last):
  File "/home/ieee/bnbserver/local/lib/python2.7/site-packages/django/core/handlers/exception.py", line 39, in inner
    response = get_response(request)
  File "/home/ieee/bnbserver/local/lib/python2.7/site-packages/django/core/handlers/base.py", line 187, in _get_response
    response = self.process_exception_by_middleware(e, request)
  File "/home/ieee/bnbserver/local/lib/python2.7/site-packages/django/core/handlers/base.py", line 185, in _get_response
    response = wrapped_callback(request, *callback_args, **callback_kwargs)
  File "/home/ieee/bnbserver/local/lib/python2.7/site-packages/django/contrib/auth/decorators.py", line 23, in _wrapped_view
    return view_func(request, *args, **kwargs)
  File "/home/ieee/bnbserver/bnb2017/fblogin/views.py", line 16, in home
    'fbid': SocialAccount.objects.get(user=request.user).uid,
  File "/home/ieee/bnbserver/local/lib/python2.7/site-packages/django/db/models/manager.py", line 85, in manager_method
    return getattr(self.get_queryset(), name)(*args, **kwargs)
  File "/home/ieee/bnbserver/local/lib/python2.7/site-packages/django/db/models/query.py", line 385, in get
    self.model._meta.object_name
DoesNotExist: SocialAccount matching query does not exist.
Internal Server Error: /favicon.ico
Traceback (most recent call last):
  File "/home/ieee/bnbserver/local/lib/python2.7/site-packages/django/core/handlers/exception.py", line 39, in inner
    response = get_response(request)
  File "/home/ieee/bnbserver/local/lib/python2.7/site-packages/django/core/handlers/base.py", line 187, in _get_response
    response = self.process_exception_by_middleware(e, request)
  File "/home/ieee/bnbserver/local/lib/python2.7/site-packages/django/core/handlers/base.py", line 185, in _get_response
    response = wrapped_callback(request, *callback_args, **callback_kwargs)
  File "/home/ieee/bnbserver/local/lib/python2.7/site-packages/django/contrib/auth/decorators.py", line 23, in _wrapped_view
    return view_func(request, *args, **kwargs)
  File "/home/ieee/bnbserver/bnb2017/fblogin/views.py", line 16, in home
    'fbid': SocialAccount.objects.get(user=request.user).uid,
  File "/home/ieee/bnbserver/local/lib/python2.7/site-packages/django/db/models/manager.py", line 85, in manager_method
    return getattr(self.get_queryset(), name)(*args, **kwargs)
  File "/home/ieee/bnbserver/local/lib/python2.7/site-packages/django/db/models/query.py", line 385, in get
    self.model._meta.object_name
DoesNotExist: SocialAccount matching query does not exist.
Internal Server Error: /favicon.ico
Traceback (most recent call last):
  File "/home/ieee/bnbserver/local/lib/python2.7/site-packages/django/core/handlers/exception.py", line 39, in inner
    response = get_response(request)
  File "/home/ieee/bnbserver/local/lib/python2.7/site-packages/django/core/handlers/base.py", line 187, in _get_response
    response = self.process_exception_by_middleware(e, request)
  File "/home/ieee/bnbserver/local/lib/python2.7/site-packages/django/core/handlers/base.py", line 185, in _get_response
    response = wrapped_callback(request, *callback_args, **callback_kwargs)
  File "/home/ieee/bnbserver/local/lib/python2.7/site-packages/django/contrib/auth/decorators.py", line 23, in _wrapped_view
    return view_func(request, *args, **kwargs)
  File "/home/ieee/bnbserver/bnb2017/fblogin/views.py", line 16, in home
    'fbid': SocialAccount.objects.get(user=request.user).uid,
  File "/home/ieee/bnbserver/local/lib/python2.7/site-packages/django/db/models/manager.py", line 85, in manager_method
    return getattr(self.get_queryset(), name)(*args, **kwargs)
  File "/home/ieee/bnbserver/local/lib/python2.7/site-packages/django/db/models/query.py", line 385, in get
    self.model._meta.object_name
DoesNotExist: SocialAccount matching query does not exist.
Internal Server Error: /favicon.ico
Traceback (most recent call last):
  File "/home/ieee/bnbserver/local/lib/python2.7/site-packages/django/core/handlers/exception.py", line 39, in inner
    response = get_response(request)
  File "/home/ieee/bnbserver/local/lib/python2.7/site-packages/django/core/handlers/base.py", line 187, in _get_response
    response = self.process_exception_by_middleware(e, request)
  File "/home/ieee/bnbserver/local/lib/python2.7/site-packages/django/core/handlers/base.py", line 185, in _get_response
    response = wrapped_callback(request, *callback_args, **callback_kwargs)
  File "/home/ieee/bnbserver/local/lib/python2.7/site-packages/django/contrib/auth/decorators.py", line 23, in _wrapped_view
    return view_func(request, *args, **kwargs)
  File "/home/ieee/bnbserver/bnb2017/fblogin/views.py", line 16, in home
    'fbid': SocialAccount.objects.get(user=request.user).uid,
  File "/home/ieee/bnbserver/local/lib/python2.7/site-packages/django/db/models/manager.py", line 85, in manager_method
    return getattr(self.get_queryset(), name)(*args, **kwargs)
  File "/home/ieee/bnbserver/local/lib/python2.7/site-packages/django/db/models/query.py", line 385, in get
    self.model._meta.object_name
DoesNotExist: SocialAccount matching query does not exist.
Internal Server Error: /favicon.ico
Traceback (most recent call last):
  File "/home/ieee/bnbserver/local/lib/python2.7/site-packages/django/core/handlers/exception.py", line 39, in inner
    response = get_response(request)
  File "/home/ieee/bnbserver/local/lib/python2.7/site-packages/django/core/handlers/base.py", line 187, in _get_response
    response = self.process_exception_by_middleware(e, request)
  File "/home/ieee/bnbserver/local/lib/python2.7/site-packages/django/core/handlers/base.py", line 185, in _get_response
    response = wrapped_callback(request, *callback_args, **callback_kwargs)
  File "/home/ieee/bnbserver/local/lib/python2.7/site-packages/django/contrib/auth/decorators.py", line 23, in _wrapped_view
    return view_func(request, *args, **kwargs)
  File "/home/ieee/bnbserver/bnb2017/fblogin/views.py", line 16, in home
    'fbid': SocialAccount.objects.get(user=request.user).uid,
  File "/home/ieee/bnbserver/local/lib/python2.7/site-packages/django/db/models/manager.py", line 85, in manager_method
    return getattr(self.get_queryset(), name)(*args, **kwargs)
  File "/home/ieee/bnbserver/local/lib/python2.7/site-packages/django/db/models/query.py", line 385, in get
    self.model._meta.object_name
DoesNotExist: SocialAccount matching query does not exist.
Internal Server Error: /favicon.ico
Traceback (most recent call last):
  File "/home/ieee/bnbserver/local/lib/python2.7/site-packages/django/core/handlers/exception.py", line 39, in inner
    response = get_response(request)
  File "/home/ieee/bnbserver/local/lib/python2.7/site-packages/django/core/handlers/base.py", line 187, in _get_response
    response = self.process_exception_by_middleware(e, request)
  File "/home/ieee/bnbserver/local/lib/python2.7/site-packages/django/core/handlers/base.py", line 185, in _get_response
    response = wrapped_callback(request, *callback_args, **callback_kwargs)
  File "/home/ieee/bnbserver/local/lib/python2.7/site-packages/django/contrib/auth/decorators.py", line 23, in _wrapped_view
    return view_func(request, *args, **kwargs)
  File "/home/ieee/bnbserver/bnb2017/fblogin/views.py", line 16, in home
    'fbid': SocialAccount.objects.get(user=request.user).uid,
  File "/home/ieee/bnbserver/local/lib/python2.7/site-packages/django/db/models/manager.py", line 85, in manager_method
    return getattr(self.get_queryset(), name)(*args, **kwargs)
  File "/home/ieee/bnbserver/local/lib/python2.7/site-packages/django/db/models/query.py", line 385, in get
    self.model._meta.object_name
DoesNotExist: SocialAccount matching query does not exist.
Internal Server Error: /favicon.ico
Traceback (most recent call last):
  File "/home/ieee/bnbserver/local/lib/python2.7/site-packages/django/core/handlers/exception.py", line 39, in inner
    response = get_response(request)
  File "/home/ieee/bnbserver/local/lib/python2.7/site-packages/django/core/handlers/base.py", line 187, in _get_response
    response = self.process_exception_by_middleware(e, request)
  File "/home/ieee/bnbserver/local/lib/python2.7/site-packages/django/core/handlers/base.py", line 185, in _get_response
    response = wrapped_callback(request, *callback_args, **callback_kwargs)
  File "/home/ieee/bnbserver/local/lib/python2.7/site-packages/django/contrib/auth/decorators.py", line 23, in _wrapped_view
    return view_func(request, *args, **kwargs)
  File "/home/ieee/bnbserver/bnb2017/fblogin/views.py", line 16, in home
    'fbid': SocialAccount.objects.get(user=request.user).uid,
  File "/home/ieee/bnbserver/local/lib/python2.7/site-packages/django/db/models/manager.py", line 85, in manager_method
    return getattr(self.get_queryset(), name)(*args, **kwargs)
  File "/home/ieee/bnbserver/local/lib/python2.7/site-packages/django/db/models/query.py", line 385, in get
    self.model._meta.object_name
DoesNotExist: SocialAccount matching query does not exist.
Internal Server Error: /favicon.ico
Traceback (most recent call last):
  File "/home/ieee/bnbserver/local/lib/python2.7/site-packages/django/core/handlers/exception.py", line 39, in inner
    response = get_response(request)
  File "/home/ieee/bnbserver/local/lib/python2.7/site-packages/django/core/handlers/base.py", line 187, in _get_response
    response = self.process_exception_by_middleware(e, request)
  File "/home/ieee/bnbserver/local/lib/python2.7/site-packages/django/core/handlers/base.py", line 185, in _get_response
    response = wrapped_callback(request, *callback_args, **callback_kwargs)
  File "/home/ieee/bnbserver/local/lib/python2.7/site-packages/django/contrib/auth/decorators.py", line 23, in _wrapped_view
    return view_func(request, *args, **kwargs)
  File "/home/ieee/bnbserver/bnb2017/fblogin/views.py", line 16, in home
    'fbid': SocialAccount.objects.get(user=request.user).uid,
  File "/home/ieee/bnbserver/local/lib/python2.7/site-packages/django/db/models/manager.py", line 85, in manager_method
    return getattr(self.get_queryset(), name)(*args, **kwargs)
  File "/home/ieee/bnbserver/local/lib/python2.7/site-packages/django/db/models/query.py", line 385, in get
    self.model._meta.object_name
DoesNotExist: SocialAccount matching query does not exist.
Internal Server Error: /favicon.ico
Traceback (most recent call last):
  File "/home/ieee/bnbserver/local/lib/python2.7/site-packages/django/core/handlers/exception.py", line 39, in inner
    response = get_response(request)
  File "/home/ieee/bnbserver/local/lib/python2.7/site-packages/django/core/handlers/base.py", line 187, in _get_response
    response = self.process_exception_by_middleware(e, request)
  File "/home/ieee/bnbserver/local/lib/python2.7/site-packages/django/core/handlers/base.py", line 185, in _get_response
    response = wrapped_callback(request, *callback_args, **callback_kwargs)
  File "/home/ieee/bnbserver/local/lib/python2.7/site-packages/django/contrib/auth/decorators.py", line 23, in _wrapped_view
    return view_func(request, *args, **kwargs)
  File "/home/ieee/bnbserver/bnb2017/fblogin/views.py", line 16, in home
    'fbid': SocialAccount.objects.get(user=request.user).uid,
  File "/home/ieee/bnbserver/local/lib/python2.7/site-packages/django/db/models/manager.py", line 85, in manager_method
    return getattr(self.get_queryset(), name)(*args, **kwargs)
  File "/home/ieee/bnbserver/local/lib/python2.7/site-packages/django/db/models/query.py", line 385, in get
    self.model._meta.object_name
DoesNotExist: SocialAccount matching query does not exist.
Internal Server Error: /favicon.ico
Traceback (most recent call last):
  File "/home/ieee/bnbserver/local/lib/python2.7/site-packages/django/core/handlers/exception.py", line 39, in inner
    response = get_response(request)
  File "/home/ieee/bnbserver/local/lib/python2.7/site-packages/django/core/handlers/base.py", line 187, in _get_response
    response = self.process_exception_by_middleware(e, request)
  File "/home/ieee/bnbserver/local/lib/python2.7/site-packages/django/core/handlers/base.py", line 185, in _get_response
    response = wrapped_callback(request, *callback_args, **callback_kwargs)
  File "/home/ieee/bnbserver/local/lib/python2.7/site-packages/django/contrib/auth/decorators.py", line 23, in _wrapped_view
    return view_func(request, *args, **kwargs)
  File "/home/ieee/bnbserver/bnb2017/fblogin/views.py", line 16, in home
    'fbid': SocialAccount.objects.get(user=request.user).uid,
  File "/home/ieee/bnbserver/local/lib/python2.7/site-packages/django/db/models/manager.py", line 85, in manager_method
    return getattr(self.get_queryset(), name)(*args, **kwargs)
  File "/home/ieee/bnbserver/local/lib/python2.7/site-packages/django/db/models/query.py", line 385, in get
    self.model._meta.object_name
DoesNotExist: SocialAccount matching query does not exist.
Internal Server Error: /favicon.ico
Traceback (most recent call last):
  File "/home/ieee/bnbserver/local/lib/python2.7/site-packages/django/core/handlers/exception.py", line 39, in inner
    response = get_response(request)
  File "/home/ieee/bnbserver/local/lib/python2.7/site-packages/django/core/handlers/base.py", line 187, in _get_response
    response = self.process_exception_by_middleware(e, request)
  File "/home/ieee/bnbserver/local/lib/python2.7/site-packages/django/core/handlers/base.py", line 185, in _get_response
    response = wrapped_callback(request, *callback_args, **callback_kwargs)
  File "/home/ieee/bnbserver/local/lib/python2.7/site-packages/django/contrib/auth/decorators.py", line 23, in _wrapped_view
    return view_func(request, *args, **kwargs)
  File "/home/ieee/bnbserver/bnb2017/fblogin/views.py", line 16, in home
    'fbid': SocialAccount.objects.get(user=request.user).uid,
  File "/home/ieee/bnbserver/local/lib/python2.7/site-packages/django/db/models/manager.py", line 85, in manager_method
    return getattr(self.get_queryset(), name)(*args, **kwargs)
  File "/home/ieee/bnbserver/local/lib/python2.7/site-packages/django/db/models/query.py", line 385, in get
    self.model._meta.object_name
DoesNotExist: SocialAccount matching query does not exist.
Internal Server Error: /favicon.ico
Traceback (most recent call last):
  File "/home/ieee/bnbserver/local/lib/python2.7/site-packages/django/core/handlers/exception.py", line 39, in inner
    response = get_response(request)
  File "/home/ieee/bnbserver/local/lib/python2.7/site-packages/django/core/handlers/base.py", line 187, in _get_response
    response = self.process_exception_by_middleware(e, request)
  File "/home/ieee/bnbserver/local/lib/python2.7/site-packages/django/core/handlers/base.py", line 185, in _get_response
    response = wrapped_callback(request, *callback_args, **callback_kwargs)
  File "/home/ieee/bnbserver/local/lib/python2.7/site-packages/django/contrib/auth/decorators.py", line 23, in _wrapped_view
    return view_func(request, *args, **kwargs)
  File "/home/ieee/bnbserver/bnb2017/fblogin/views.py", line 16, in home
    'fbid': SocialAccount.objects.get(user=request.user).uid,
  File "/home/ieee/bnbserver/local/lib/python2.7/site-packages/django/db/models/manager.py", line 85, in manager_method
    return getattr(self.get_queryset(), name)(*args, **kwargs)
  File "/home/ieee/bnbserver/local/lib/python2.7/site-packages/django/db/models/query.py", line 385, in get
    self.model._meta.object_name
DoesNotExist: SocialAccount matching query does not exist.
Internal Server Error: /favicon.ico
Traceback (most recent call last):
  File "/home/ieee/bnbserver/local/lib/python2.7/site-packages/django/core/handlers/exception.py", line 39, in inner
    response = get_response(request)
  File "/home/ieee/bnbserver/local/lib/python2.7/site-packages/django/core/handlers/base.py", line 187, in _get_response
    response = self.process_exception_by_middleware(e, request)
  File "/home/ieee/bnbserver/local/lib/python2.7/site-packages/django/core/handlers/base.py", line 185, in _get_response
    response = wrapped_callback(request, *callback_args, **callback_kwargs)
  File "/home/ieee/bnbserver/local/lib/python2.7/site-packages/django/contrib/auth/decorators.py", line 23, in _wrapped_view
    return view_func(request, *args, **kwargs)
  File "/home/ieee/bnbserver/bnb2017/fblogin/views.py", line 16, in home
    'fbid': SocialAccount.objects.get(user=request.user).uid,
  File "/home/ieee/bnbserver/local/lib/python2.7/site-packages/django/db/models/manager.py", line 85, in manager_method
    return getattr(self.get_queryset(), name)(*args, **kwargs)
  File "/home/ieee/bnbserver/local/lib/python2.7/site-packages/django/db/models/query.py", line 385, in get
    self.model._meta.object_name
DoesNotExist: SocialAccount matching query does not exist.
Internal Server Error: /favicon.ico
Traceback (most recent call last):
  File "/home/ieee/bnbserver/local/lib/python2.7/site-packages/django/core/handlers/exception.py", line 39, in inner
    response = get_response(request)
  File "/home/ieee/bnbserver/local/lib/python2.7/site-packages/django/core/handlers/base.py", line 187, in _get_response
    response = self.process_exception_by_middleware(e, request)
  File "/home/ieee/bnbserver/local/lib/python2.7/site-packages/django/core/handlers/base.py", line 185, in _get_response
    response = wrapped_callback(request, *callback_args, **callback_kwargs)
  File "/home/ieee/bnbserver/local/lib/python2.7/site-packages/django/contrib/auth/decorators.py", line 23, in _wrapped_view
    return view_func(request, *args, **kwargs)
  File "/home/ieee/bnbserver/bnb2017/fblogin/views.py", line 16, in home
    'fbid': SocialAccount.objects.get(user=request.user).uid,
  File "/home/ieee/bnbserver/local/lib/python2.7/site-packages/django/db/models/manager.py", line 85, in manager_method
    return getattr(self.get_queryset(), name)(*args, **kwargs)
  File "/home/ieee/bnbserver/local/lib/python2.7/site-packages/django/db/models/query.py", line 385, in get
    self.model._meta.object_name
DoesNotExist: SocialAccount matching query does not exist.
Internal Server Error: /favicon.ico
Traceback (most recent call last):
  File "/home/ieee/bnbserver/local/lib/python2.7/site-packages/django/core/handlers/exception.py", line 39, in inner
    response = get_response(request)
  File "/home/ieee/bnbserver/local/lib/python2.7/site-packages/django/core/handlers/base.py", line 187, in _get_response
    response = self.process_exception_by_middleware(e, request)
  File "/home/ieee/bnbserver/local/lib/python2.7/site-packages/django/core/handlers/base.py", line 185, in _get_response
    response = wrapped_callback(request, *callback_args, **callback_kwargs)
  File "/home/ieee/bnbserver/local/lib/python2.7/site-packages/django/contrib/auth/decorators.py", line 23, in _wrapped_view
    return view_func(request, *args, **kwargs)
  File "/home/ieee/bnbserver/bnb2017/fblogin/views.py", line 16, in home
    'fbid': SocialAccount.objects.get(user=request.user).uid,
  File "/home/ieee/bnbserver/local/lib/python2.7/site-packages/django/db/models/manager.py", line 85, in manager_method
    return getattr(self.get_queryset(), name)(*args, **kwargs)
  File "/home/ieee/bnbserver/local/lib/python2.7/site-packages/django/db/models/query.py", line 385, in get
    self.model._meta.object_name
DoesNotExist: SocialAccount matching query does not exist.
Internal Server Error: /favicon.ico
Traceback (most recent call last):
  File "/home/ieee/bnbserver/local/lib/python2.7/site-packages/django/core/handlers/exception.py", line 39, in inner
    response = get_response(request)
  File "/home/ieee/bnbserver/local/lib/python2.7/site-packages/django/core/handlers/base.py", line 187, in _get_response
    response = self.process_exception_by_middleware(e, request)
  File "/home/ieee/bnbserver/local/lib/python2.7/site-packages/django/core/handlers/base.py", line 185, in _get_response
    response = wrapped_callback(request, *callback_args, **callback_kwargs)
  File "/home/ieee/bnbserver/local/lib/python2.7/site-packages/django/contrib/auth/decorators.py", line 23, in _wrapped_view
    return view_func(request, *args, **kwargs)
  File "/home/ieee/bnbserver/bnb2017/fblogin/views.py", line 16, in home
    'fbid': SocialAccount.objects.get(user=request.user).uid,
  File "/home/ieee/bnbserver/local/lib/python2.7/site-packages/django/db/models/manager.py", line 85, in manager_method
    return getattr(self.get_queryset(), name)(*args, **kwargs)
  File "/home/ieee/bnbserver/local/lib/python2.7/site-packages/django/db/models/query.py", line 385, in get
    self.model._meta.object_name
DoesNotExist: SocialAccount matching query does not exist.
Internal Server Error: /favicon.ico
Traceback (most recent call last):
  File "/home/ieee/bnbserver/local/lib/python2.7/site-packages/django/core/handlers/exception.py", line 39, in inner
    response = get_response(request)
  File "/home/ieee/bnbserver/local/lib/python2.7/site-packages/django/core/handlers/base.py", line 187, in _get_response
    response = self.process_exception_by_middleware(e, request)
  File "/home/ieee/bnbserver/local/lib/python2.7/site-packages/django/core/handlers/base.py", line 185, in _get_response
    response = wrapped_callback(request, *callback_args, **callback_kwargs)
  File "/home/ieee/bnbserver/local/lib/python2.7/site-packages/django/contrib/auth/decorators.py", line 23, in _wrapped_view
    return view_func(request, *args, **kwargs)
  File "/home/ieee/bnbserver/bnb2017/fblogin/views.py", line 16, in home
    'fbid': SocialAccount.objects.get(user=request.user).uid,
  File "/home/ieee/bnbserver/local/lib/python2.7/site-packages/django/db/models/manager.py", line 85, in manager_method
    return getattr(self.get_queryset(), name)(*args, **kwargs)
  File "/home/ieee/bnbserver/local/lib/python2.7/site-packages/django/db/models/query.py", line 385, in get
    self.model._meta.object_name
DoesNotExist: SocialAccount matching query does not exist.
Internal Server Error: /favicon.ico
Traceback (most recent call last):
  File "/home/ieee/bnbserver/local/lib/python2.7/site-packages/django/core/handlers/exception.py", line 39, in inner
    response = get_response(request)
  File "/home/ieee/bnbserver/local/lib/python2.7/site-packages/django/core/handlers/base.py", line 187, in _get_response
    response = self.process_exception_by_middleware(e, request)
  File "/home/ieee/bnbserver/local/lib/python2.7/site-packages/django/core/handlers/base.py", line 185, in _get_response
    response = wrapped_callback(request, *callback_args, **callback_kwargs)
  File "/home/ieee/bnbserver/local/lib/python2.7/site-packages/django/contrib/auth/decorators.py", line 23, in _wrapped_view
    return view_func(request, *args, **kwargs)
  File "/home/ieee/bnbserver/bnb2017/fblogin/views.py", line 16, in home
    'fbid': SocialAccount.objects.get(user=request.user).uid,
  File "/home/ieee/bnbserver/local/lib/python2.7/site-packages/django/db/models/manager.py", line 85, in manager_method
    return getattr(self.get_queryset(), name)(*args, **kwargs)
  File "/home/ieee/bnbserver/local/lib/python2.7/site-packages/django/db/models/query.py", line 385, in get
    self.model._meta.object_name
DoesNotExist: SocialAccount matching query does not exist.
Internal Server Error: /favicon.ico
Traceback (most recent call last):
  File "/home/ieee/bnbserver/local/lib/python2.7/site-packages/django/core/handlers/exception.py", line 39, in inner
    response = get_response(request)
  File "/home/ieee/bnbserver/local/lib/python2.7/site-packages/django/core/handlers/base.py", line 187, in _get_response
    response = self.process_exception_by_middleware(e, request)
  File "/home/ieee/bnbserver/local/lib/python2.7/site-packages/django/core/handlers/base.py", line 185, in _get_response
    response = wrapped_callback(request, *callback_args, **callback_kwargs)
  File "/home/ieee/bnbserver/local/lib/python2.7/site-packages/django/contrib/auth/decorators.py", line 23, in _wrapped_view
    return view_func(request, *args, **kwargs)
  File "/home/ieee/bnbserver/bnb2017/fblogin/views.py", line 16, in home
    'fbid': SocialAccount.objects.get(user=request.user).uid,
  File "/home/ieee/bnbserver/local/lib/python2.7/site-packages/django/db/models/manager.py", line 85, in manager_method
    return getattr(self.get_queryset(), name)(*args, **kwargs)
  File "/home/ieee/bnbserver/local/lib/python2.7/site-packages/django/db/models/query.py", line 385, in get
    self.model._meta.object_name
DoesNotExist: SocialAccount matching query does not exist.
Internal Server Error: /favicon.ico
Traceback (most recent call last):
  File "/home/ieee/bnbserver/local/lib/python2.7/site-packages/django/core/handlers/exception.py", line 39, in inner
    response = get_response(request)
  File "/home/ieee/bnbserver/local/lib/python2.7/site-packages/django/core/handlers/base.py", line 187, in _get_response
    response = self.process_exception_by_middleware(e, request)
  File "/home/ieee/bnbserver/local/lib/python2.7/site-packages/django/core/handlers/base.py", line 185, in _get_response
    response = wrapped_callback(request, *callback_args, **callback_kwargs)
  File "/home/ieee/bnbserver/local/lib/python2.7/site-packages/django/contrib/auth/decorators.py", line 23, in _wrapped_view
    return view_func(request, *args, **kwargs)
  File "/home/ieee/bnbserver/bnb2017/fblogin/views.py", line 16, in home
    'fbid': SocialAccount.objects.get(user=request.user).uid,
  File "/home/ieee/bnbserver/local/lib/python2.7/site-packages/django/db/models/manager.py", line 85, in manager_method
    return getattr(self.get_queryset(), name)(*args, **kwargs)
  File "/home/ieee/bnbserver/local/lib/python2.7/site-packages/django/db/models/query.py", line 385, in get
    self.model._meta.object_name
DoesNotExist: SocialAccount matching query does not exist.
Internal Server Error: /favicon.ico
Traceback (most recent call last):
  File "/home/ieee/bnbserver/local/lib/python2.7/site-packages/django/core/handlers/exception.py", line 39, in inner
    response = get_response(request)
  File "/home/ieee/bnbserver/local/lib/python2.7/site-packages/django/core/handlers/base.py", line 187, in _get_response
    response = self.process_exception_by_middleware(e, request)
  File "/home/ieee/bnbserver/local/lib/python2.7/site-packages/django/core/handlers/base.py", line 185, in _get_response
    response = wrapped_callback(request, *callback_args, **callback_kwargs)
  File "/home/ieee/bnbserver/local/lib/python2.7/site-packages/django/contrib/auth/decorators.py", line 23, in _wrapped_view
    return view_func(request, *args, **kwargs)
  File "/home/ieee/bnbserver/bnb2017/fblogin/views.py", line 16, in home
    'fbid': SocialAccount.objects.get(user=request.user).uid,
  File "/home/ieee/bnbserver/local/lib/python2.7/site-packages/django/db/models/manager.py", line 85, in manager_method
    return getattr(self.get_queryset(), name)(*args, **kwargs)
  File "/home/ieee/bnbserver/local/lib/python2.7/site-packages/django/db/models/query.py", line 385, in get
    self.model._meta.object_name
DoesNotExist: SocialAccount matching query does not exist.
Internal Server Error: /favicon.ico
Traceback (most recent call last):
  File "/home/ieee/bnbserver/local/lib/python2.7/site-packages/django/core/handlers/exception.py", line 39, in inner
    response = get_response(request)
  File "/home/ieee/bnbserver/local/lib/python2.7/site-packages/django/core/handlers/base.py", line 187, in _get_response
    response = self.process_exception_by_middleware(e, request)
  File "/home/ieee/bnbserver/local/lib/python2.7/site-packages/django/core/handlers/base.py", line 185, in _get_response
    response = wrapped_callback(request, *callback_args, **callback_kwargs)
  File "/home/ieee/bnbserver/local/lib/python2.7/site-packages/django/contrib/auth/decorators.py", line 23, in _wrapped_view
    return view_func(request, *args, **kwargs)
  File "/home/ieee/bnbserver/bnb2017/fblogin/views.py", line 16, in home
    'fbid': SocialAccount.objects.get(user=request.user).uid,
  File "/home/ieee/bnbserver/local/lib/python2.7/site-packages/django/db/models/manager.py", line 85, in manager_method
    return getattr(self.get_queryset(), name)(*args, **kwargs)
  File "/home/ieee/bnbserver/local/lib/python2.7/site-packages/django/db/models/query.py", line 385, in get
    self.model._meta.object_name
DoesNotExist: SocialAccount matching query does not exist.
Internal Server Error: /favicon.ico
Traceback (most recent call last):
  File "/home/ieee/bnbserver/local/lib/python2.7/site-packages/django/core/handlers/exception.py", line 39, in inner
    response = get_response(request)
  File "/home/ieee/bnbserver/local/lib/python2.7/site-packages/django/core/handlers/base.py", line 187, in _get_response
    response = self.process_exception_by_middleware(e, request)
  File "/home/ieee/bnbserver/local/lib/python2.7/site-packages/django/core/handlers/base.py", line 185, in _get_response
    response = wrapped_callback(request, *callback_args, **callback_kwargs)
  File "/home/ieee/bnbserver/local/lib/python2.7/site-packages/django/contrib/auth/decorators.py", line 23, in _wrapped_view
    return view_func(request, *args, **kwargs)
  File "/home/ieee/bnbserver/bnb2017/fblogin/views.py", line 16, in home
    'fbid': SocialAccount.objects.get(user=request.user).uid,
  File "/home/ieee/bnbserver/local/lib/python2.7/site-packages/django/db/models/manager.py", line 85, in manager_method
    return getattr(self.get_queryset(), name)(*args, **kwargs)
  File "/home/ieee/bnbserver/local/lib/python2.7/site-packages/django/db/models/query.py", line 385, in get
    self.model._meta.object_name
DoesNotExist: SocialAccount matching query does not exist.
Internal Server Error: /favicon.ico
Traceback (most recent call last):
  File "/home/ieee/bnbserver/local/lib/python2.7/site-packages/django/core/handlers/exception.py", line 39, in inner
    response = get_response(request)
  File "/home/ieee/bnbserver/local/lib/python2.7/site-packages/django/core/handlers/base.py", line 187, in _get_response
    response = self.process_exception_by_middleware(e, request)
  File "/home/ieee/bnbserver/local/lib/python2.7/site-packages/django/core/handlers/base.py", line 185, in _get_response
    response = wrapped_callback(request, *callback_args, **callback_kwargs)
  File "/home/ieee/bnbserver/local/lib/python2.7/site-packages/django/contrib/auth/decorators.py", line 23, in _wrapped_view
    return view_func(request, *args, **kwargs)
  File "/home/ieee/bnbserver/bnb2017/fblogin/views.py", line 16, in home
    'fbid': SocialAccount.objects.get(user=request.user).uid,
  File "/home/ieee/bnbserver/local/lib/python2.7/site-packages/django/db/models/manager.py", line 85, in manager_method
    return getattr(self.get_queryset(), name)(*args, **kwargs)
  File "/home/ieee/bnbserver/local/lib/python2.7/site-packages/django/db/models/query.py", line 385, in get
    self.model._meta.object_name
DoesNotExist: SocialAccount matching query does not exist.
Internal Server Error: /favicon.ico
Traceback (most recent call last):
  File "/home/ieee/bnbserver/local/lib/python2.7/site-packages/django/core/handlers/exception.py", line 39, in inner
    response = get_response(request)
  File "/home/ieee/bnbserver/local/lib/python2.7/site-packages/django/core/handlers/base.py", line 187, in _get_response
    response = self.process_exception_by_middleware(e, request)
  File "/home/ieee/bnbserver/local/lib/python2.7/site-packages/django/core/handlers/base.py", line 185, in _get_response
    response = wrapped_callback(request, *callback_args, **callback_kwargs)
  File "/home/ieee/bnbserver/local/lib/python2.7/site-packages/django/contrib/auth/decorators.py", line 23, in _wrapped_view
    return view_func(request, *args, **kwargs)
  File "/home/ieee/bnbserver/bnb2017/fblogin/views.py", line 16, in home
    'fbid': SocialAccount.objects.get(user=request.user).uid,
  File "/home/ieee/bnbserver/local/lib/python2.7/site-packages/django/db/models/manager.py", line 85, in manager_method
    return getattr(self.get_queryset(), name)(*args, **kwargs)
  File "/home/ieee/bnbserver/local/lib/python2.7/site-packages/django/db/models/query.py", line 385, in get
    self.model._meta.object_name
DoesNotExist: SocialAccount matching query does not exist.
Internal Server Error: /favicon.ico
Traceback (most recent call last):
  File "/home/ieee/bnbserver/local/lib/python2.7/site-packages/django/core/handlers/exception.py", line 39, in inner
    response = get_response(request)
  File "/home/ieee/bnbserver/local/lib/python2.7/site-packages/django/core/handlers/base.py", line 187, in _get_response
    response = self.process_exception_by_middleware(e, request)
  File "/home/ieee/bnbserver/local/lib/python2.7/site-packages/django/core/handlers/base.py", line 185, in _get_response
    response = wrapped_callback(request, *callback_args, **callback_kwargs)
  File "/home/ieee/bnbserver/local/lib/python2.7/site-packages/django/contrib/auth/decorators.py", line 23, in _wrapped_view
    return view_func(request, *args, **kwargs)
  File "/home/ieee/bnbserver/bnb2017/fblogin/views.py", line 16, in home
    'fbid': SocialAccount.objects.get(user=request.user).uid,
  File "/home/ieee/bnbserver/local/lib/python2.7/site-packages/django/db/models/manager.py", line 85, in manager_method
    return getattr(self.get_queryset(), name)(*args, **kwargs)
  File "/home/ieee/bnbserver/local/lib/python2.7/site-packages/django/db/models/query.py", line 385, in get
    self.model._meta.object_name
DoesNotExist: SocialAccount matching query does not exist.
Internal Server Error: /favicon.ico
Traceback (most recent call last):
  File "/home/ieee/bnbserver/local/lib/python2.7/site-packages/django/core/handlers/exception.py", line 39, in inner
    response = get_response(request)
  File "/home/ieee/bnbserver/local/lib/python2.7/site-packages/django/core/handlers/base.py", line 187, in _get_response
    response = self.process_exception_by_middleware(e, request)
  File "/home/ieee/bnbserver/local/lib/python2.7/site-packages/django/core/handlers/base.py", line 185, in _get_response
    response = wrapped_callback(request, *callback_args, **callback_kwargs)
  File "/home/ieee/bnbserver/local/lib/python2.7/site-packages/django/contrib/auth/decorators.py", line 23, in _wrapped_view
    return view_func(request, *args, **kwargs)
  File "/home/ieee/bnbserver/bnb2017/fblogin/views.py", line 16, in home
    'fbid': SocialAccount.objects.get(user=request.user).uid,
  File "/home/ieee/bnbserver/local/lib/python2.7/site-packages/django/db/models/manager.py", line 85, in manager_method
    return getattr(self.get_queryset(), name)(*args, **kwargs)
  File "/home/ieee/bnbserver/local/lib/python2.7/site-packages/django/db/models/query.py", line 385, in get
    self.model._meta.object_name
DoesNotExist: SocialAccount matching query does not exist.
Internal Server Error: /favicon.ico
Traceback (most recent call last):
  File "/home/ieee/bnbserver/local/lib/python2.7/site-packages/django/core/handlers/exception.py", line 39, in inner
    response = get_response(request)
  File "/home/ieee/bnbserver/local/lib/python2.7/site-packages/django/core/handlers/base.py", line 187, in _get_response
    response = self.process_exception_by_middleware(e, request)
  File "/home/ieee/bnbserver/local/lib/python2.7/site-packages/django/core/handlers/base.py", line 185, in _get_response
    response = wrapped_callback(request, *callback_args, **callback_kwargs)
  File "/home/ieee/bnbserver/local/lib/python2.7/site-packages/django/contrib/auth/decorators.py", line 23, in _wrapped_view
    return view_func(request, *args, **kwargs)
  File "/home/ieee/bnbserver/bnb2017/fblogin/views.py", line 16, in home
    'fbid': SocialAccount.objects.get(user=request.user).uid,
  File "/home/ieee/bnbserver/local/lib/python2.7/site-packages/django/db/models/manager.py", line 85, in manager_method
    return getattr(self.get_queryset(), name)(*args, **kwargs)
  File "/home/ieee/bnbserver/local/lib/python2.7/site-packages/django/db/models/query.py", line 385, in get
    self.model._meta.object_name
DoesNotExist: SocialAccount matching query does not exist.
Internal Server Error: /favicon.ico
Traceback (most recent call last):
  File "/home/ieee/bnbserver/local/lib/python2.7/site-packages/django/core/handlers/exception.py", line 39, in inner
    response = get_response(request)
  File "/home/ieee/bnbserver/local/lib/python2.7/site-packages/django/core/handlers/base.py", line 187, in _get_response
    response = self.process_exception_by_middleware(e, request)
  File "/home/ieee/bnbserver/local/lib/python2.7/site-packages/django/core/handlers/base.py", line 185, in _get_response
    response = wrapped_callback(request, *callback_args, **callback_kwargs)
  File "/home/ieee/bnbserver/local/lib/python2.7/site-packages/django/contrib/auth/decorators.py", line 23, in _wrapped_view
    return view_func(request, *args, **kwargs)
  File "/home/ieee/bnbserver/bnb2017/fblogin/views.py", line 16, in home
    'fbid': SocialAccount.objects.get(user=request.user).uid,
  File "/home/ieee/bnbserver/local/lib/python2.7/site-packages/django/db/models/manager.py", line 85, in manager_method
    return getattr(self.get_queryset(), name)(*args, **kwargs)
  File "/home/ieee/bnbserver/local/lib/python2.7/site-packages/django/db/models/query.py", line 385, in get
    self.model._meta.object_name
DoesNotExist: SocialAccount matching query does not exist.
Internal Server Error: /favicon.ico
Traceback (most recent call last):
  File "/home/ieee/bnbserver/local/lib/python2.7/site-packages/django/core/handlers/exception.py", line 39, in inner
    response = get_response(request)
  File "/home/ieee/bnbserver/local/lib/python2.7/site-packages/django/core/handlers/base.py", line 187, in _get_response
    response = self.process_exception_by_middleware(e, request)
  File "/home/ieee/bnbserver/local/lib/python2.7/site-packages/django/core/handlers/base.py", line 185, in _get_response
    response = wrapped_callback(request, *callback_args, **callback_kwargs)
  File "/home/ieee/bnbserver/local/lib/python2.7/site-packages/django/contrib/auth/decorators.py", line 23, in _wrapped_view
    return view_func(request, *args, **kwargs)
  File "/home/ieee/bnbserver/bnb2017/fblogin/views.py", line 16, in home
    'fbid': SocialAccount.objects.get(user=request.user).uid,
  File "/home/ieee/bnbserver/local/lib/python2.7/site-packages/django/db/models/manager.py", line 85, in manager_method
    return getattr(self.get_queryset(), name)(*args, **kwargs)
  File "/home/ieee/bnbserver/local/lib/python2.7/site-packages/django/db/models/query.py", line 385, in get
    self.model._meta.object_name
DoesNotExist: SocialAccount matching query does not exist.
Internal Server Error: /favicon.ico
Traceback (most recent call last):
  File "/home/ieee/bnbserver/local/lib/python2.7/site-packages/django/core/handlers/exception.py", line 39, in inner
    response = get_response(request)
  File "/home/ieee/bnbserver/local/lib/python2.7/site-packages/django/core/handlers/base.py", line 187, in _get_response
    response = self.process_exception_by_middleware(e, request)
  File "/home/ieee/bnbserver/local/lib/python2.7/site-packages/django/core/handlers/base.py", line 185, in _get_response
    response = wrapped_callback(request, *callback_args, **callback_kwargs)
  File "/home/ieee/bnbserver/local/lib/python2.7/site-packages/django/contrib/auth/decorators.py", line 23, in _wrapped_view
    return view_func(request, *args, **kwargs)
  File "/home/ieee/bnbserver/bnb2017/fblogin/views.py", line 16, in home
    'fbid': SocialAccount.objects.get(user=request.user).uid,
  File "/home/ieee/bnbserver/local/lib/python2.7/site-packages/django/db/models/manager.py", line 85, in manager_method
    return getattr(self.get_queryset(), name)(*args, **kwargs)
  File "/home/ieee/bnbserver/local/lib/python2.7/site-packages/django/db/models/query.py", line 385, in get
    self.model._meta.object_name
DoesNotExist: SocialAccount matching query does not exist.
Internal Server Error: /favicon.ico
Traceback (most recent call last):
  File "/home/ieee/bnbserver/local/lib/python2.7/site-packages/django/core/handlers/exception.py", line 39, in inner
    response = get_response(request)
  File "/home/ieee/bnbserver/local/lib/python2.7/site-packages/django/core/handlers/base.py", line 187, in _get_response
    response = self.process_exception_by_middleware(e, request)
  File "/home/ieee/bnbserver/local/lib/python2.7/site-packages/django/core/handlers/base.py", line 185, in _get_response
    response = wrapped_callback(request, *callback_args, **callback_kwargs)
  File "/home/ieee/bnbserver/local/lib/python2.7/site-packages/django/contrib/auth/decorators.py", line 23, in _wrapped_view
    return view_func(request, *args, **kwargs)
  File "/home/ieee/bnbserver/bnb2017/fblogin/views.py", line 16, in home
    'fbid': SocialAccount.objects.get(user=request.user).uid,
  File "/home/ieee/bnbserver/local/lib/python2.7/site-packages/django/db/models/manager.py", line 85, in manager_method
    return getattr(self.get_queryset(), name)(*args, **kwargs)
  File "/home/ieee/bnbserver/local/lib/python2.7/site-packages/django/db/models/query.py", line 385, in get
    self.model._meta.object_name
DoesNotExist: SocialAccount matching query does not exist.
Internal Server Error: /favicon.ico
Traceback (most recent call last):
  File "/home/ieee/bnbserver/local/lib/python2.7/site-packages/django/core/handlers/exception.py", line 39, in inner
    response = get_response(request)
  File "/home/ieee/bnbserver/local/lib/python2.7/site-packages/django/core/handlers/base.py", line 187, in _get_response
    response = self.process_exception_by_middleware(e, request)
  File "/home/ieee/bnbserver/local/lib/python2.7/site-packages/django/core/handlers/base.py", line 185, in _get_response
    response = wrapped_callback(request, *callback_args, **callback_kwargs)
  File "/home/ieee/bnbserver/local/lib/python2.7/site-packages/django/contrib/auth/decorators.py", line 23, in _wrapped_view
    return view_func(request, *args, **kwargs)
  File "/home/ieee/bnbserver/bnb2017/fblogin/views.py", line 16, in home
    'fbid': SocialAccount.objects.get(user=request.user).uid,
  File "/home/ieee/bnbserver/local/lib/python2.7/site-packages/django/db/models/manager.py", line 85, in manager_method
    return getattr(self.get_queryset(), name)(*args, **kwargs)
  File "/home/ieee/bnbserver/local/lib/python2.7/site-packages/django/db/models/query.py", line 385, in get
    self.model._meta.object_name
DoesNotExist: SocialAccount matching query does not exist.
Internal Server Error: /favicon.ico
Traceback (most recent call last):
  File "/home/ieee/bnbserver/local/lib/python2.7/site-packages/django/core/handlers/exception.py", line 39, in inner
    response = get_response(request)
  File "/home/ieee/bnbserver/local/lib/python2.7/site-packages/django/core/handlers/base.py", line 187, in _get_response
    response = self.process_exception_by_middleware(e, request)
  File "/home/ieee/bnbserver/local/lib/python2.7/site-packages/django/core/handlers/base.py", line 185, in _get_response
    response = wrapped_callback(request, *callback_args, **callback_kwargs)
  File "/home/ieee/bnbserver/local/lib/python2.7/site-packages/django/contrib/auth/decorators.py", line 23, in _wrapped_view
    return view_func(request, *args, **kwargs)
  File "/home/ieee/bnbserver/bnb2017/fblogin/views.py", line 16, in home
    'fbid': SocialAccount.objects.get(user=request.user).uid,
  File "/home/ieee/bnbserver/local/lib/python2.7/site-packages/django/db/models/manager.py", line 85, in manager_method
    return getattr(self.get_queryset(), name)(*args, **kwargs)
  File "/home/ieee/bnbserver/local/lib/python2.7/site-packages/django/db/models/query.py", line 385, in get
    self.model._meta.object_name
DoesNotExist: SocialAccount matching query does not exist.
Internal Server Error: /favicon.ico
Traceback (most recent call last):
  File "/home/ieee/bnbserver/local/lib/python2.7/site-packages/django/core/handlers/exception.py", line 39, in inner
    response = get_response(request)
  File "/home/ieee/bnbserver/local/lib/python2.7/site-packages/django/core/handlers/base.py", line 187, in _get_response
    response = self.process_exception_by_middleware(e, request)
  File "/home/ieee/bnbserver/local/lib/python2.7/site-packages/django/core/handlers/base.py", line 185, in _get_response
    response = wrapped_callback(request, *callback_args, **callback_kwargs)
  File "/home/ieee/bnbserver/local/lib/python2.7/site-packages/django/contrib/auth/decorators.py", line 23, in _wrapped_view
    return view_func(request, *args, **kwargs)
  File "/home/ieee/bnbserver/bnb2017/fblogin/views.py", line 16, in home
    'fbid': SocialAccount.objects.get(user=request.user).uid,
  File "/home/ieee/bnbserver/local/lib/python2.7/site-packages/django/db/models/manager.py", line 85, in manager_method
    return getattr(self.get_queryset(), name)(*args, **kwargs)
  File "/home/ieee/bnbserver/local/lib/python2.7/site-packages/django/db/models/query.py", line 385, in get
    self.model._meta.object_name
DoesNotExist: SocialAccount matching query does not exist.
Internal Server Error: /favicon.ico
Traceback (most recent call last):
  File "/home/ieee/bnbserver/local/lib/python2.7/site-packages/django/core/handlers/exception.py", line 39, in inner
    response = get_response(request)
  File "/home/ieee/bnbserver/local/lib/python2.7/site-packages/django/core/handlers/base.py", line 187, in _get_response
    response = self.process_exception_by_middleware(e, request)
  File "/home/ieee/bnbserver/local/lib/python2.7/site-packages/django/core/handlers/base.py", line 185, in _get_response
    response = wrapped_callback(request, *callback_args, **callback_kwargs)
  File "/home/ieee/bnbserver/local/lib/python2.7/site-packages/django/contrib/auth/decorators.py", line 23, in _wrapped_view
    return view_func(request, *args, **kwargs)
  File "/home/ieee/bnbserver/bnb2017/fblogin/views.py", line 16, in home
    'fbid': SocialAccount.objects.get(user=request.user).uid,
  File "/home/ieee/bnbserver/local/lib/python2.7/site-packages/django/db/models/manager.py", line 85, in manager_method
    return getattr(self.get_queryset(), name)(*args, **kwargs)
  File "/home/ieee/bnbserver/local/lib/python2.7/site-packages/django/db/models/query.py", line 385, in get
    self.model._meta.object_name
DoesNotExist: SocialAccount matching query does not exist.
Internal Server Error: /favicon.ico
Traceback (most recent call last):
  File "/home/ieee/bnbserver/local/lib/python2.7/site-packages/django/core/handlers/exception.py", line 39, in inner
    response = get_response(request)
  File "/home/ieee/bnbserver/local/lib/python2.7/site-packages/django/core/handlers/base.py", line 187, in _get_response
    response = self.process_exception_by_middleware(e, request)
  File "/home/ieee/bnbserver/local/lib/python2.7/site-packages/django/core/handlers/base.py", line 185, in _get_response
    response = wrapped_callback(request, *callback_args, **callback_kwargs)
  File "/home/ieee/bnbserver/local/lib/python2.7/site-packages/django/contrib/auth/decorators.py", line 23, in _wrapped_view
    return view_func(request, *args, **kwargs)
  File "/home/ieee/bnbserver/bnb2017/fblogin/views.py", line 16, in home
    'fbid': SocialAccount.objects.get(user=request.user).uid,
  File "/home/ieee/bnbserver/local/lib/python2.7/site-packages/django/db/models/manager.py", line 85, in manager_method
    return getattr(self.get_queryset(), name)(*args, **kwargs)
  File "/home/ieee/bnbserver/local/lib/python2.7/site-packages/django/db/models/query.py", line 385, in get
    self.model._meta.object_name
DoesNotExist: SocialAccount matching query does not exist.
Internal Server Error: /favicon.ico
Traceback (most recent call last):
  File "/home/ieee/bnbserver/local/lib/python2.7/site-packages/django/core/handlers/exception.py", line 39, in inner
    response = get_response(request)
  File "/home/ieee/bnbserver/local/lib/python2.7/site-packages/django/core/handlers/base.py", line 187, in _get_response
    response = self.process_exception_by_middleware(e, request)
  File "/home/ieee/bnbserver/local/lib/python2.7/site-packages/django/core/handlers/base.py", line 185, in _get_response
    response = wrapped_callback(request, *callback_args, **callback_kwargs)
  File "/home/ieee/bnbserver/local/lib/python2.7/site-packages/django/contrib/auth/decorators.py", line 23, in _wrapped_view
    return view_func(request, *args, **kwargs)
  File "/home/ieee/bnbserver/bnb2017/fblogin/views.py", line 16, in home
    'fbid': SocialAccount.objects.get(user=request.user).uid,
  File "/home/ieee/bnbserver/local/lib/python2.7/site-packages/django/db/models/manager.py", line 85, in manager_method
    return getattr(self.get_queryset(), name)(*args, **kwargs)
  File "/home/ieee/bnbserver/local/lib/python2.7/site-packages/django/db/models/query.py", line 385, in get
    self.model._meta.object_name
DoesNotExist: SocialAccount matching query does not exist.
Internal Server Error: /favicon.ico
Traceback (most recent call last):
  File "/home/ieee/bnbserver/local/lib/python2.7/site-packages/django/core/handlers/exception.py", line 39, in inner
    response = get_response(request)
  File "/home/ieee/bnbserver/local/lib/python2.7/site-packages/django/core/handlers/base.py", line 187, in _get_response
    response = self.process_exception_by_middleware(e, request)
  File "/home/ieee/bnbserver/local/lib/python2.7/site-packages/django/core/handlers/base.py", line 185, in _get_response
    response = wrapped_callback(request, *callback_args, **callback_kwargs)
  File "/home/ieee/bnbserver/local/lib/python2.7/site-packages/django/contrib/auth/decorators.py", line 23, in _wrapped_view
    return view_func(request, *args, **kwargs)
  File "/home/ieee/bnbserver/bnb2017/fblogin/views.py", line 16, in home
    'fbid': SocialAccount.objects.get(user=request.user).uid,
  File "/home/ieee/bnbserver/local/lib/python2.7/site-packages/django/db/models/manager.py", line 85, in manager_method
    return getattr(self.get_queryset(), name)(*args, **kwargs)
  File "/home/ieee/bnbserver/local/lib/python2.7/site-packages/django/db/models/query.py", line 385, in get
    self.model._meta.object_name
DoesNotExist: SocialAccount matching query does not exist.
Internal Server Error: /favicon.ico
Traceback (most recent call last):
  File "/home/ieee/bnbserver/local/lib/python2.7/site-packages/django/core/handlers/exception.py", line 39, in inner
    response = get_response(request)
  File "/home/ieee/bnbserver/local/lib/python2.7/site-packages/django/core/handlers/base.py", line 187, in _get_response
    response = self.process_exception_by_middleware(e, request)
  File "/home/ieee/bnbserver/local/lib/python2.7/site-packages/django/core/handlers/base.py", line 185, in _get_response
    response = wrapped_callback(request, *callback_args, **callback_kwargs)
  File "/home/ieee/bnbserver/local/lib/python2.7/site-packages/django/contrib/auth/decorators.py", line 23, in _wrapped_view
    return view_func(request, *args, **kwargs)
  File "/home/ieee/bnbserver/bnb2017/fblogin/views.py", line 16, in home
    'fbid': SocialAccount.objects.get(user=request.user).uid,
  File "/home/ieee/bnbserver/local/lib/python2.7/site-packages/django/db/models/manager.py", line 85, in manager_method
    return getattr(self.get_queryset(), name)(*args, **kwargs)
  File "/home/ieee/bnbserver/local/lib/python2.7/site-packages/django/db/models/query.py", line 385, in get
    self.model._meta.object_name
DoesNotExist: SocialAccount matching query does not exist.
Internal Server Error: /favicon.ico
Traceback (most recent call last):
  File "/home/ieee/bnbserver/local/lib/python2.7/site-packages/django/core/handlers/exception.py", line 39, in inner
    response = get_response(request)
  File "/home/ieee/bnbserver/local/lib/python2.7/site-packages/django/core/handlers/base.py", line 187, in _get_response
    response = self.process_exception_by_middleware(e, request)
  File "/home/ieee/bnbserver/local/lib/python2.7/site-packages/django/core/handlers/base.py", line 185, in _get_response
    response = wrapped_callback(request, *callback_args, **callback_kwargs)
  File "/home/ieee/bnbserver/local/lib/python2.7/site-packages/django/contrib/auth/decorators.py", line 23, in _wrapped_view
    return view_func(request, *args, **kwargs)
  File "/home/ieee/bnbserver/bnb2017/fblogin/views.py", line 16, in home
    'fbid': SocialAccount.objects.get(user=request.user).uid,
  File "/home/ieee/bnbserver/local/lib/python2.7/site-packages/django/db/models/manager.py", line 85, in manager_method
    return getattr(self.get_queryset(), name)(*args, **kwargs)
  File "/home/ieee/bnbserver/local/lib/python2.7/site-packages/django/db/models/query.py", line 385, in get
    self.model._meta.object_name
DoesNotExist: SocialAccount matching query does not exist.
Internal Server Error: /favicon.ico
Traceback (most recent call last):
  File "/home/ieee/bnbserver/local/lib/python2.7/site-packages/django/core/handlers/exception.py", line 39, in inner
    response = get_response(request)
  File "/home/ieee/bnbserver/local/lib/python2.7/site-packages/django/core/handlers/base.py", line 187, in _get_response
    response = self.process_exception_by_middleware(e, request)
  File "/home/ieee/bnbserver/local/lib/python2.7/site-packages/django/core/handlers/base.py", line 185, in _get_response
    response = wrapped_callback(request, *callback_args, **callback_kwargs)
  File "/home/ieee/bnbserver/local/lib/python2.7/site-packages/django/contrib/auth/decorators.py", line 23, in _wrapped_view
    return view_func(request, *args, **kwargs)
  File "/home/ieee/bnbserver/bnb2017/fblogin/views.py", line 16, in home
    'fbid': SocialAccount.objects.get(user=request.user).uid,
  File "/home/ieee/bnbserver/local/lib/python2.7/site-packages/django/db/models/manager.py", line 85, in manager_method
    return getattr(self.get_queryset(), name)(*args, **kwargs)
  File "/home/ieee/bnbserver/local/lib/python2.7/site-packages/django/db/models/query.py", line 385, in get
    self.model._meta.object_name
DoesNotExist: SocialAccount matching query does not exist.
Internal Server Error: /favicon.ico
Traceback (most recent call last):
  File "/home/ieee/bnbserver/local/lib/python2.7/site-packages/django/core/handlers/exception.py", line 39, in inner
    response = get_response(request)
  File "/home/ieee/bnbserver/local/lib/python2.7/site-packages/django/core/handlers/base.py", line 187, in _get_response
    response = self.process_exception_by_middleware(e, request)
  File "/home/ieee/bnbserver/local/lib/python2.7/site-packages/django/core/handlers/base.py", line 185, in _get_response
    response = wrapped_callback(request, *callback_args, **callback_kwargs)
  File "/home/ieee/bnbserver/local/lib/python2.7/site-packages/django/contrib/auth/decorators.py", line 23, in _wrapped_view
    return view_func(request, *args, **kwargs)
  File "/home/ieee/bnbserver/bnb2017/fblogin/views.py", line 16, in home
    'fbid': SocialAccount.objects.get(user=request.user).uid,
  File "/home/ieee/bnbserver/local/lib/python2.7/site-packages/django/db/models/manager.py", line 85, in manager_method
    return getattr(self.get_queryset(), name)(*args, **kwargs)
  File "/home/ieee/bnbserver/local/lib/python2.7/site-packages/django/db/models/query.py", line 385, in get
    self.model._meta.object_name
DoesNotExist: SocialAccount matching query does not exist.
Internal Server Error: /favicon.ico
Traceback (most recent call last):
  File "/home/ieee/bnbserver/local/lib/python2.7/site-packages/django/core/handlers/exception.py", line 39, in inner
    response = get_response(request)
  File "/home/ieee/bnbserver/local/lib/python2.7/site-packages/django/core/handlers/base.py", line 187, in _get_response
    response = self.process_exception_by_middleware(e, request)
  File "/home/ieee/bnbserver/local/lib/python2.7/site-packages/django/core/handlers/base.py", line 185, in _get_response
    response = wrapped_callback(request, *callback_args, **callback_kwargs)
  File "/home/ieee/bnbserver/local/lib/python2.7/site-packages/django/contrib/auth/decorators.py", line 23, in _wrapped_view
    return view_func(request, *args, **kwargs)
  File "/home/ieee/bnbserver/bnb2017/fblogin/views.py", line 16, in home
    'fbid': SocialAccount.objects.get(user=request.user).uid,
  File "/home/ieee/bnbserver/local/lib/python2.7/site-packages/django/db/models/manager.py", line 85, in manager_method
    return getattr(self.get_queryset(), name)(*args, **kwargs)
  File "/home/ieee/bnbserver/local/lib/python2.7/site-packages/django/db/models/query.py", line 385, in get
    self.model._meta.object_name
DoesNotExist: SocialAccount matching query does not exist.
Internal Server Error: /favicon.ico
Traceback (most recent call last):
  File "/home/ieee/bnbserver/local/lib/python2.7/site-packages/django/core/handlers/exception.py", line 39, in inner
    response = get_response(request)
  File "/home/ieee/bnbserver/local/lib/python2.7/site-packages/django/core/handlers/base.py", line 187, in _get_response
    response = self.process_exception_by_middleware(e, request)
  File "/home/ieee/bnbserver/local/lib/python2.7/site-packages/django/core/handlers/base.py", line 185, in _get_response
    response = wrapped_callback(request, *callback_args, **callback_kwargs)
  File "/home/ieee/bnbserver/local/lib/python2.7/site-packages/django/contrib/auth/decorators.py", line 23, in _wrapped_view
    return view_func(request, *args, **kwargs)
  File "/home/ieee/bnbserver/bnb2017/fblogin/views.py", line 16, in home
    'fbid': SocialAccount.objects.get(user=request.user).uid,
  File "/home/ieee/bnbserver/local/lib/python2.7/site-packages/django/db/models/manager.py", line 85, in manager_method
    return getattr(self.get_queryset(), name)(*args, **kwargs)
  File "/home/ieee/bnbserver/local/lib/python2.7/site-packages/django/db/models/query.py", line 385, in get
    self.model._meta.object_name
DoesNotExist: SocialAccount matching query does not exist.
Internal Server Error: /favicon.ico
Traceback (most recent call last):
  File "/home/ieee/bnbserver/local/lib/python2.7/site-packages/django/core/handlers/exception.py", line 39, in inner
    response = get_response(request)
  File "/home/ieee/bnbserver/local/lib/python2.7/site-packages/django/core/handlers/base.py", line 187, in _get_response
    response = self.process_exception_by_middleware(e, request)
  File "/home/ieee/bnbserver/local/lib/python2.7/site-packages/django/core/handlers/base.py", line 185, in _get_response
    response = wrapped_callback(request, *callback_args, **callback_kwargs)
  File "/home/ieee/bnbserver/local/lib/python2.7/site-packages/django/contrib/auth/decorators.py", line 23, in _wrapped_view
    return view_func(request, *args, **kwargs)
  File "/home/ieee/bnbserver/bnb2017/fblogin/views.py", line 16, in home
    'fbid': SocialAccount.objects.get(user=request.user).uid,
  File "/home/ieee/bnbserver/local/lib/python2.7/site-packages/django/db/models/manager.py", line 85, in manager_method
    return getattr(self.get_queryset(), name)(*args, **kwargs)
  File "/home/ieee/bnbserver/local/lib/python2.7/site-packages/django/db/models/query.py", line 385, in get
    self.model._meta.object_name
DoesNotExist: SocialAccount matching query does not exist.
Internal Server Error: /favicon.ico
Traceback (most recent call last):
  File "/home/ieee/bnbserver/local/lib/python2.7/site-packages/django/core/handlers/exception.py", line 39, in inner
    response = get_response(request)
  File "/home/ieee/bnbserver/local/lib/python2.7/site-packages/django/core/handlers/base.py", line 187, in _get_response
    response = self.process_exception_by_middleware(e, request)
  File "/home/ieee/bnbserver/local/lib/python2.7/site-packages/django/core/handlers/base.py", line 185, in _get_response
    response = wrapped_callback(request, *callback_args, **callback_kwargs)
  File "/home/ieee/bnbserver/local/lib/python2.7/site-packages/django/contrib/auth/decorators.py", line 23, in _wrapped_view
    return view_func(request, *args, **kwargs)
  File "/home/ieee/bnbserver/bnb2017/fblogin/views.py", line 16, in home
    'fbid': SocialAccount.objects.get(user=request.user).uid,
  File "/home/ieee/bnbserver/local/lib/python2.7/site-packages/django/db/models/manager.py", line 85, in manager_method
    return getattr(self.get_queryset(), name)(*args, **kwargs)
  File "/home/ieee/bnbserver/local/lib/python2.7/site-packages/django/db/models/query.py", line 385, in get
    self.model._meta.object_name
DoesNotExist: SocialAccount matching query does not exist.
Internal Server Error: /favicon.ico
Traceback (most recent call last):
  File "/home/ieee/bnbserver/local/lib/python2.7/site-packages/django/core/handlers/exception.py", line 39, in inner
    response = get_response(request)
  File "/home/ieee/bnbserver/local/lib/python2.7/site-packages/django/core/handlers/base.py", line 187, in _get_response
    response = self.process_exception_by_middleware(e, request)
  File "/home/ieee/bnbserver/local/lib/python2.7/site-packages/django/core/handlers/base.py", line 185, in _get_response
    response = wrapped_callback(request, *callback_args, **callback_kwargs)
  File "/home/ieee/bnbserver/local/lib/python2.7/site-packages/django/contrib/auth/decorators.py", line 23, in _wrapped_view
    return view_func(request, *args, **kwargs)
  File "/home/ieee/bnbserver/bnb2017/fblogin/views.py", line 16, in home
    'fbid': SocialAccount.objects.get(user=request.user).uid,
  File "/home/ieee/bnbserver/local/lib/python2.7/site-packages/django/db/models/manager.py", line 85, in manager_method
    return getattr(self.get_queryset(), name)(*args, **kwargs)
  File "/home/ieee/bnbserver/local/lib/python2.7/site-packages/django/db/models/query.py", line 385, in get
    self.model._meta.object_name
DoesNotExist: SocialAccount matching query does not exist.
Internal Server Error: /favicon.ico
Traceback (most recent call last):
  File "/home/ieee/bnbserver/local/lib/python2.7/site-packages/django/core/handlers/exception.py", line 39, in inner
    response = get_response(request)
  File "/home/ieee/bnbserver/local/lib/python2.7/site-packages/django/core/handlers/base.py", line 187, in _get_response
    response = self.process_exception_by_middleware(e, request)
  File "/home/ieee/bnbserver/local/lib/python2.7/site-packages/django/core/handlers/base.py", line 185, in _get_response
    response = wrapped_callback(request, *callback_args, **callback_kwargs)
  File "/home/ieee/bnbserver/local/lib/python2.7/site-packages/django/contrib/auth/decorators.py", line 23, in _wrapped_view
    return view_func(request, *args, **kwargs)
  File "/home/ieee/bnbserver/bnb2017/fblogin/views.py", line 16, in home
    'fbid': SocialAccount.objects.get(user=request.user).uid,
  File "/home/ieee/bnbserver/local/lib/python2.7/site-packages/django/db/models/manager.py", line 85, in manager_method
    return getattr(self.get_queryset(), name)(*args, **kwargs)
  File "/home/ieee/bnbserver/local/lib/python2.7/site-packages/django/db/models/query.py", line 385, in get
    self.model._meta.object_name
DoesNotExist: SocialAccount matching query does not exist.
Internal Server Error: /favicon.ico
Traceback (most recent call last):
  File "/home/ieee/bnbserver/local/lib/python2.7/site-packages/django/core/handlers/exception.py", line 39, in inner
    response = get_response(request)
  File "/home/ieee/bnbserver/local/lib/python2.7/site-packages/django/core/handlers/base.py", line 187, in _get_response
    response = self.process_exception_by_middleware(e, request)
  File "/home/ieee/bnbserver/local/lib/python2.7/site-packages/django/core/handlers/base.py", line 185, in _get_response
    response = wrapped_callback(request, *callback_args, **callback_kwargs)
  File "/home/ieee/bnbserver/local/lib/python2.7/site-packages/django/contrib/auth/decorators.py", line 23, in _wrapped_view
    return view_func(request, *args, **kwargs)
  File "/home/ieee/bnbserver/bnb2017/fblogin/views.py", line 16, in home
    'fbid': SocialAccount.objects.get(user=request.user).uid,
  File "/home/ieee/bnbserver/local/lib/python2.7/site-packages/django/db/models/manager.py", line 85, in manager_method
    return getattr(self.get_queryset(), name)(*args, **kwargs)
  File "/home/ieee/bnbserver/local/lib/python2.7/site-packages/django/db/models/query.py", line 385, in get
    self.model._meta.object_name
DoesNotExist: SocialAccount matching query does not exist.
Internal Server Error: /favicon.ico
Traceback (most recent call last):
  File "/home/ieee/bnbserver/local/lib/python2.7/site-packages/django/core/handlers/exception.py", line 39, in inner
    response = get_response(request)
  File "/home/ieee/bnbserver/local/lib/python2.7/site-packages/django/core/handlers/base.py", line 187, in _get_response
    response = self.process_exception_by_middleware(e, request)
  File "/home/ieee/bnbserver/local/lib/python2.7/site-packages/django/core/handlers/base.py", line 185, in _get_response
    response = wrapped_callback(request, *callback_args, **callback_kwargs)
  File "/home/ieee/bnbserver/local/lib/python2.7/site-packages/django/contrib/auth/decorators.py", line 23, in _wrapped_view
    return view_func(request, *args, **kwargs)
  File "/home/ieee/bnbserver/bnb2017/fblogin/views.py", line 16, in home
    'fbid': SocialAccount.objects.get(user=request.user).uid,
  File "/home/ieee/bnbserver/local/lib/python2.7/site-packages/django/db/models/manager.py", line 85, in manager_method
    return getattr(self.get_queryset(), name)(*args, **kwargs)
  File "/home/ieee/bnbserver/local/lib/python2.7/site-packages/django/db/models/query.py", line 385, in get
    self.model._meta.object_name
DoesNotExist: SocialAccount matching query does not exist.
Internal Server Error: /favicon.ico
Traceback (most recent call last):
  File "/home/ieee/bnbserver/local/lib/python2.7/site-packages/django/core/handlers/exception.py", line 39, in inner
    response = get_response(request)
  File "/home/ieee/bnbserver/local/lib/python2.7/site-packages/django/core/handlers/base.py", line 187, in _get_response
    response = self.process_exception_by_middleware(e, request)
  File "/home/ieee/bnbserver/local/lib/python2.7/site-packages/django/core/handlers/base.py", line 185, in _get_response
    response = wrapped_callback(request, *callback_args, **callback_kwargs)
  File "/home/ieee/bnbserver/local/lib/python2.7/site-packages/django/contrib/auth/decorators.py", line 23, in _wrapped_view
    return view_func(request, *args, **kwargs)
  File "/home/ieee/bnbserver/bnb2017/fblogin/views.py", line 16, in home
    'fbid': SocialAccount.objects.get(user=request.user).uid,
  File "/home/ieee/bnbserver/local/lib/python2.7/site-packages/django/db/models/manager.py", line 85, in manager_method
    return getattr(self.get_queryset(), name)(*args, **kwargs)
  File "/home/ieee/bnbserver/local/lib/python2.7/site-packages/django/db/models/query.py", line 385, in get
    self.model._meta.object_name
DoesNotExist: SocialAccount matching query does not exist.
Internal Server Error: /favicon.ico
Traceback (most recent call last):
  File "/home/ieee/bnbserver/local/lib/python2.7/site-packages/django/core/handlers/exception.py", line 39, in inner
    response = get_response(request)
  File "/home/ieee/bnbserver/local/lib/python2.7/site-packages/django/core/handlers/base.py", line 187, in _get_response
    response = self.process_exception_by_middleware(e, request)
  File "/home/ieee/bnbserver/local/lib/python2.7/site-packages/django/core/handlers/base.py", line 185, in _get_response
    response = wrapped_callback(request, *callback_args, **callback_kwargs)
  File "/home/ieee/bnbserver/local/lib/python2.7/site-packages/django/contrib/auth/decorators.py", line 23, in _wrapped_view
    return view_func(request, *args, **kwargs)
  File "/home/ieee/bnbserver/bnb2017/fblogin/views.py", line 16, in home
    'fbid': SocialAccount.objects.get(user=request.user).uid,
  File "/home/ieee/bnbserver/local/lib/python2.7/site-packages/django/db/models/manager.py", line 85, in manager_method
    return getattr(self.get_queryset(), name)(*args, **kwargs)
  File "/home/ieee/bnbserver/local/lib/python2.7/site-packages/django/db/models/query.py", line 385, in get
    self.model._meta.object_name
DoesNotExist: SocialAccount matching query does not exist.
Internal Server Error: /favicon.ico
Traceback (most recent call last):
  File "/home/ieee/bnbserver/local/lib/python2.7/site-packages/django/core/handlers/exception.py", line 39, in inner
    response = get_response(request)
  File "/home/ieee/bnbserver/local/lib/python2.7/site-packages/django/core/handlers/base.py", line 187, in _get_response
    response = self.process_exception_by_middleware(e, request)
  File "/home/ieee/bnbserver/local/lib/python2.7/site-packages/django/core/handlers/base.py", line 185, in _get_response
    response = wrapped_callback(request, *callback_args, **callback_kwargs)
  File "/home/ieee/bnbserver/local/lib/python2.7/site-packages/django/contrib/auth/decorators.py", line 23, in _wrapped_view
    return view_func(request, *args, **kwargs)
  File "/home/ieee/bnbserver/bnb2017/fblogin/views.py", line 16, in home
    'fbid': SocialAccount.objects.get(user=request.user).uid,
  File "/home/ieee/bnbserver/local/lib/python2.7/site-packages/django/db/models/manager.py", line 85, in manager_method
    return getattr(self.get_queryset(), name)(*args, **kwargs)
  File "/home/ieee/bnbserver/local/lib/python2.7/site-packages/django/db/models/query.py", line 385, in get
    self.model._meta.object_name
DoesNotExist: SocialAccount matching query does not exist.
Internal Server Error: /favicon.ico
Traceback (most recent call last):
  File "/home/ieee/bnbserver/local/lib/python2.7/site-packages/django/core/handlers/exception.py", line 39, in inner
    response = get_response(request)
  File "/home/ieee/bnbserver/local/lib/python2.7/site-packages/django/core/handlers/base.py", line 187, in _get_response
    response = self.process_exception_by_middleware(e, request)
  File "/home/ieee/bnbserver/local/lib/python2.7/site-packages/django/core/handlers/base.py", line 185, in _get_response
    response = wrapped_callback(request, *callback_args, **callback_kwargs)
  File "/home/ieee/bnbserver/local/lib/python2.7/site-packages/django/contrib/auth/decorators.py", line 23, in _wrapped_view
    return view_func(request, *args, **kwargs)
  File "/home/ieee/bnbserver/bnb2017/fblogin/views.py", line 16, in home
    'fbid': SocialAccount.objects.get(user=request.user).uid,
  File "/home/ieee/bnbserver/local/lib/python2.7/site-packages/django/db/models/manager.py", line 85, in manager_method
    return getattr(self.get_queryset(), name)(*args, **kwargs)
  File "/home/ieee/bnbserver/local/lib/python2.7/site-packages/django/db/models/query.py", line 385, in get
    self.model._meta.object_name
DoesNotExist: SocialAccount matching query does not exist.
Internal Server Error: /favicon.ico
Traceback (most recent call last):
  File "/home/ieee/bnbserver/local/lib/python2.7/site-packages/django/core/handlers/exception.py", line 39, in inner
    response = get_response(request)
  File "/home/ieee/bnbserver/local/lib/python2.7/site-packages/django/core/handlers/base.py", line 187, in _get_response
    response = self.process_exception_by_middleware(e, request)
  File "/home/ieee/bnbserver/local/lib/python2.7/site-packages/django/core/handlers/base.py", line 185, in _get_response
    response = wrapped_callback(request, *callback_args, **callback_kwargs)
  File "/home/ieee/bnbserver/local/lib/python2.7/site-packages/django/contrib/auth/decorators.py", line 23, in _wrapped_view
    return view_func(request, *args, **kwargs)
  File "/home/ieee/bnbserver/bnb2017/fblogin/views.py", line 16, in home
    'fbid': SocialAccount.objects.get(user=request.user).uid,
  File "/home/ieee/bnbserver/local/lib/python2.7/site-packages/django/db/models/manager.py", line 85, in manager_method
    return getattr(self.get_queryset(), name)(*args, **kwargs)
  File "/home/ieee/bnbserver/local/lib/python2.7/site-packages/django/db/models/query.py", line 385, in get
    self.model._meta.object_name
DoesNotExist: SocialAccount matching query does not exist.
Internal Server Error: /favicon.ico
Traceback (most recent call last):
  File "/home/ieee/bnbserver/local/lib/python2.7/site-packages/django/core/handlers/exception.py", line 39, in inner
    response = get_response(request)
  File "/home/ieee/bnbserver/local/lib/python2.7/site-packages/django/core/handlers/base.py", line 187, in _get_response
    response = self.process_exception_by_middleware(e, request)
  File "/home/ieee/bnbserver/local/lib/python2.7/site-packages/django/core/handlers/base.py", line 185, in _get_response
    response = wrapped_callback(request, *callback_args, **callback_kwargs)
  File "/home/ieee/bnbserver/local/lib/python2.7/site-packages/django/contrib/auth/decorators.py", line 23, in _wrapped_view
    return view_func(request, *args, **kwargs)
  File "/home/ieee/bnbserver/bnb2017/fblogin/views.py", line 16, in home
    'fbid': SocialAccount.objects.get(user=request.user).uid,
  File "/home/ieee/bnbserver/local/lib/python2.7/site-packages/django/db/models/manager.py", line 85, in manager_method
    return getattr(self.get_queryset(), name)(*args, **kwargs)
  File "/home/ieee/bnbserver/local/lib/python2.7/site-packages/django/db/models/query.py", line 385, in get
    self.model._meta.object_name
DoesNotExist: SocialAccount matching query does not exist.
Internal Server Error: /favicon.ico
Traceback (most recent call last):
  File "/home/ieee/bnbserver/local/lib/python2.7/site-packages/django/core/handlers/exception.py", line 39, in inner
    response = get_response(request)
  File "/home/ieee/bnbserver/local/lib/python2.7/site-packages/django/core/handlers/base.py", line 187, in _get_response
    response = self.process_exception_by_middleware(e, request)
  File "/home/ieee/bnbserver/local/lib/python2.7/site-packages/django/core/handlers/base.py", line 185, in _get_response
    response = wrapped_callback(request, *callback_args, **callback_kwargs)
  File "/home/ieee/bnbserver/local/lib/python2.7/site-packages/django/contrib/auth/decorators.py", line 23, in _wrapped_view
    return view_func(request, *args, **kwargs)
  File "/home/ieee/bnbserver/bnb2017/fblogin/views.py", line 16, in home
    'fbid': SocialAccount.objects.get(user=request.user).uid,
  File "/home/ieee/bnbserver/local/lib/python2.7/site-packages/django/db/models/manager.py", line 85, in manager_method
    return getattr(self.get_queryset(), name)(*args, **kwargs)
  File "/home/ieee/bnbserver/local/lib/python2.7/site-packages/django/db/models/query.py", line 385, in get
    self.model._meta.object_name
DoesNotExist: SocialAccount matching query does not exist.
Internal Server Error: /favicon.ico
Traceback (most recent call last):
  File "/home/ieee/bnbserver/local/lib/python2.7/site-packages/django/core/handlers/exception.py", line 39, in inner
    response = get_response(request)
  File "/home/ieee/bnbserver/local/lib/python2.7/site-packages/django/core/handlers/base.py", line 187, in _get_response
    response = self.process_exception_by_middleware(e, request)
  File "/home/ieee/bnbserver/local/lib/python2.7/site-packages/django/core/handlers/base.py", line 185, in _get_response
    response = wrapped_callback(request, *callback_args, **callback_kwargs)
  File "/home/ieee/bnbserver/local/lib/python2.7/site-packages/django/contrib/auth/decorators.py", line 23, in _wrapped_view
    return view_func(request, *args, **kwargs)
  File "/home/ieee/bnbserver/bnb2017/fblogin/views.py", line 16, in home
    'fbid': SocialAccount.objects.get(user=request.user).uid,
  File "/home/ieee/bnbserver/local/lib/python2.7/site-packages/django/db/models/manager.py", line 85, in manager_method
    return getattr(self.get_queryset(), name)(*args, **kwargs)
  File "/home/ieee/bnbserver/local/lib/python2.7/site-packages/django/db/models/query.py", line 385, in get
    self.model._meta.object_name
DoesNotExist: SocialAccount matching query does not exist.
Internal Server Error: /favicon.ico
Traceback (most recent call last):
  File "/home/ieee/bnbserver/local/lib/python2.7/site-packages/django/core/handlers/exception.py", line 39, in inner
    response = get_response(request)
  File "/home/ieee/bnbserver/local/lib/python2.7/site-packages/django/core/handlers/base.py", line 187, in _get_response
    response = self.process_exception_by_middleware(e, request)
  File "/home/ieee/bnbserver/local/lib/python2.7/site-packages/django/core/handlers/base.py", line 185, in _get_response
    response = wrapped_callback(request, *callback_args, **callback_kwargs)
  File "/home/ieee/bnbserver/local/lib/python2.7/site-packages/django/contrib/auth/decorators.py", line 23, in _wrapped_view
    return view_func(request, *args, **kwargs)
  File "/home/ieee/bnbserver/bnb2017/fblogin/views.py", line 16, in home
    'fbid': SocialAccount.objects.get(user=request.user).uid,
  File "/home/ieee/bnbserver/local/lib/python2.7/site-packages/django/db/models/manager.py", line 85, in manager_method
    return getattr(self.get_queryset(), name)(*args, **kwargs)
  File "/home/ieee/bnbserver/local/lib/python2.7/site-packages/django/db/models/query.py", line 385, in get
    self.model._meta.object_name
DoesNotExist: SocialAccount matching query does not exist.
Internal Server Error: /favicon.ico
Traceback (most recent call last):
  File "/home/ieee/bnbserver/local/lib/python2.7/site-packages/django/core/handlers/exception.py", line 39, in inner
    response = get_response(request)
  File "/home/ieee/bnbserver/local/lib/python2.7/site-packages/django/core/handlers/base.py", line 187, in _get_response
    response = self.process_exception_by_middleware(e, request)
  File "/home/ieee/bnbserver/local/lib/python2.7/site-packages/django/core/handlers/base.py", line 185, in _get_response
    response = wrapped_callback(request, *callback_args, **callback_kwargs)
  File "/home/ieee/bnbserver/local/lib/python2.7/site-packages/django/contrib/auth/decorators.py", line 23, in _wrapped_view
    return view_func(request, *args, **kwargs)
  File "/home/ieee/bnbserver/bnb2017/fblogin/views.py", line 16, in home
    'fbid': SocialAccount.objects.get(user=request.user).uid,
  File "/home/ieee/bnbserver/local/lib/python2.7/site-packages/django/db/models/manager.py", line 85, in manager_method
    return getattr(self.get_queryset(), name)(*args, **kwargs)
  File "/home/ieee/bnbserver/local/lib/python2.7/site-packages/django/db/models/query.py", line 385, in get
    self.model._meta.object_name
DoesNotExist: SocialAccount matching query does not exist.
Internal Server Error: /favicon.ico
Traceback (most recent call last):
  File "/home/ieee/bnbserver/local/lib/python2.7/site-packages/django/core/handlers/exception.py", line 39, in inner
    response = get_response(request)
  File "/home/ieee/bnbserver/local/lib/python2.7/site-packages/django/core/handlers/base.py", line 187, in _get_response
    response = self.process_exception_by_middleware(e, request)
  File "/home/ieee/bnbserver/local/lib/python2.7/site-packages/django/core/handlers/base.py", line 185, in _get_response
    response = wrapped_callback(request, *callback_args, **callback_kwargs)
  File "/home/ieee/bnbserver/local/lib/python2.7/site-packages/django/contrib/auth/decorators.py", line 23, in _wrapped_view
    return view_func(request, *args, **kwargs)
  File "/home/ieee/bnbserver/bnb2017/fblogin/views.py", line 16, in home
    'fbid': SocialAccount.objects.get(user=request.user).uid,
  File "/home/ieee/bnbserver/local/lib/python2.7/site-packages/django/db/models/manager.py", line 85, in manager_method
    return getattr(self.get_queryset(), name)(*args, **kwargs)
  File "/home/ieee/bnbserver/local/lib/python2.7/site-packages/django/db/models/query.py", line 385, in get
    self.model._meta.object_name
DoesNotExist: SocialAccount matching query does not exist.
Internal Server Error: /favicon.ico
Traceback (most recent call last):
  File "/home/ieee/bnbserver/local/lib/python2.7/site-packages/django/core/handlers/exception.py", line 39, in inner
    response = get_response(request)
  File "/home/ieee/bnbserver/local/lib/python2.7/site-packages/django/core/handlers/base.py", line 187, in _get_response
    response = self.process_exception_by_middleware(e, request)
  File "/home/ieee/bnbserver/local/lib/python2.7/site-packages/django/core/handlers/base.py", line 185, in _get_response
    response = wrapped_callback(request, *callback_args, **callback_kwargs)
  File "/home/ieee/bnbserver/local/lib/python2.7/site-packages/django/contrib/auth/decorators.py", line 23, in _wrapped_view
    return view_func(request, *args, **kwargs)
  File "/home/ieee/bnbserver/bnb2017/fblogin/views.py", line 16, in home
    'fbid': SocialAccount.objects.get(user=request.user).uid,
  File "/home/ieee/bnbserver/local/lib/python2.7/site-packages/django/db/models/manager.py", line 85, in manager_method
    return getattr(self.get_queryset(), name)(*args, **kwargs)
  File "/home/ieee/bnbserver/local/lib/python2.7/site-packages/django/db/models/query.py", line 385, in get
    self.model._meta.object_name
DoesNotExist: SocialAccount matching query does not exist.
Internal Server Error: /favicon.ico
Traceback (most recent call last):
  File "/home/ieee/bnbserver/local/lib/python2.7/site-packages/django/core/handlers/exception.py", line 39, in inner
    response = get_response(request)
  File "/home/ieee/bnbserver/local/lib/python2.7/site-packages/django/core/handlers/base.py", line 187, in _get_response
    response = self.process_exception_by_middleware(e, request)
  File "/home/ieee/bnbserver/local/lib/python2.7/site-packages/django/core/handlers/base.py", line 185, in _get_response
    response = wrapped_callback(request, *callback_args, **callback_kwargs)
  File "/home/ieee/bnbserver/local/lib/python2.7/site-packages/django/contrib/auth/decorators.py", line 23, in _wrapped_view
    return view_func(request, *args, **kwargs)
  File "/home/ieee/bnbserver/bnb2017/fblogin/views.py", line 16, in home
    'fbid': SocialAccount.objects.get(user=request.user).uid,
  File "/home/ieee/bnbserver/local/lib/python2.7/site-packages/django/db/models/manager.py", line 85, in manager_method
    return getattr(self.get_queryset(), name)(*args, **kwargs)
  File "/home/ieee/bnbserver/local/lib/python2.7/site-packages/django/db/models/query.py", line 385, in get
    self.model._meta.object_name
DoesNotExist: SocialAccount matching query does not exist.
Internal Server Error: /favicon.ico
Traceback (most recent call last):
  File "/home/ieee/bnbserver/local/lib/python2.7/site-packages/django/core/handlers/exception.py", line 39, in inner
    response = get_response(request)
  File "/home/ieee/bnbserver/local/lib/python2.7/site-packages/django/core/handlers/base.py", line 187, in _get_response
    response = self.process_exception_by_middleware(e, request)
  File "/home/ieee/bnbserver/local/lib/python2.7/site-packages/django/core/handlers/base.py", line 185, in _get_response
    response = wrapped_callback(request, *callback_args, **callback_kwargs)
  File "/home/ieee/bnbserver/local/lib/python2.7/site-packages/django/contrib/auth/decorators.py", line 23, in _wrapped_view
    return view_func(request, *args, **kwargs)
  File "/home/ieee/bnbserver/bnb2017/fblogin/views.py", line 16, in home
    'fbid': SocialAccount.objects.get(user=request.user).uid,
  File "/home/ieee/bnbserver/local/lib/python2.7/site-packages/django/db/models/manager.py", line 85, in manager_method
    return getattr(self.get_queryset(), name)(*args, **kwargs)
  File "/home/ieee/bnbserver/local/lib/python2.7/site-packages/django/db/models/query.py", line 385, in get
    self.model._meta.object_name
DoesNotExist: SocialAccount matching query does not exist.
Internal Server Error: /favicon.ico
Traceback (most recent call last):
  File "/home/ieee/bnbserver/local/lib/python2.7/site-packages/django/core/handlers/exception.py", line 39, in inner
    response = get_response(request)
  File "/home/ieee/bnbserver/local/lib/python2.7/site-packages/django/core/handlers/base.py", line 187, in _get_response
    response = self.process_exception_by_middleware(e, request)
  File "/home/ieee/bnbserver/local/lib/python2.7/site-packages/django/core/handlers/base.py", line 185, in _get_response
    response = wrapped_callback(request, *callback_args, **callback_kwargs)
  File "/home/ieee/bnbserver/local/lib/python2.7/site-packages/django/contrib/auth/decorators.py", line 23, in _wrapped_view
    return view_func(request, *args, **kwargs)
  File "/home/ieee/bnbserver/bnb2017/fblogin/views.py", line 16, in home
    'fbid': SocialAccount.objects.get(user=request.user).uid,
  File "/home/ieee/bnbserver/local/lib/python2.7/site-packages/django/db/models/manager.py", line 85, in manager_method
    return getattr(self.get_queryset(), name)(*args, **kwargs)
  File "/home/ieee/bnbserver/local/lib/python2.7/site-packages/django/db/models/query.py", line 385, in get
    self.model._meta.object_name
DoesNotExist: SocialAccount matching query does not exist.
Internal Server Error: /favicon.ico
Traceback (most recent call last):
  File "/home/ieee/bnbserver/local/lib/python2.7/site-packages/django/core/handlers/exception.py", line 39, in inner
    response = get_response(request)
  File "/home/ieee/bnbserver/local/lib/python2.7/site-packages/django/core/handlers/base.py", line 187, in _get_response
    response = self.process_exception_by_middleware(e, request)
  File "/home/ieee/bnbserver/local/lib/python2.7/site-packages/django/core/handlers/base.py", line 185, in _get_response
    response = wrapped_callback(request, *callback_args, **callback_kwargs)
  File "/home/ieee/bnbserver/local/lib/python2.7/site-packages/django/contrib/auth/decorators.py", line 23, in _wrapped_view
    return view_func(request, *args, **kwargs)
  File "/home/ieee/bnbserver/bnb2017/fblogin/views.py", line 16, in home
    'fbid': SocialAccount.objects.get(user=request.user).uid,
  File "/home/ieee/bnbserver/local/lib/python2.7/site-packages/django/db/models/manager.py", line 85, in manager_method
    return getattr(self.get_queryset(), name)(*args, **kwargs)
  File "/home/ieee/bnbserver/local/lib/python2.7/site-packages/django/db/models/query.py", line 385, in get
    self.model._meta.object_name
DoesNotExist: SocialAccount matching query does not exist.
Internal Server Error: /favicon.ico
Traceback (most recent call last):
  File "/home/ieee/bnbserver/local/lib/python2.7/site-packages/django/core/handlers/exception.py", line 39, in inner
    response = get_response(request)
  File "/home/ieee/bnbserver/local/lib/python2.7/site-packages/django/core/handlers/base.py", line 187, in _get_response
    response = self.process_exception_by_middleware(e, request)
  File "/home/ieee/bnbserver/local/lib/python2.7/site-packages/django/core/handlers/base.py", line 185, in _get_response
    response = wrapped_callback(request, *callback_args, **callback_kwargs)
  File "/home/ieee/bnbserver/local/lib/python2.7/site-packages/django/contrib/auth/decorators.py", line 23, in _wrapped_view
    return view_func(request, *args, **kwargs)
  File "/home/ieee/bnbserver/bnb2017/fblogin/views.py", line 16, in home
    'fbid': SocialAccount.objects.get(user=request.user).uid,
  File "/home/ieee/bnbserver/local/lib/python2.7/site-packages/django/db/models/manager.py", line 85, in manager_method
    return getattr(self.get_queryset(), name)(*args, **kwargs)
  File "/home/ieee/bnbserver/local/lib/python2.7/site-packages/django/db/models/query.py", line 385, in get
    self.model._meta.object_name
DoesNotExist: SocialAccount matching query does not exist.
Internal Server Error: /favicon.ico
Traceback (most recent call last):
  File "/home/ieee/bnbserver/local/lib/python2.7/site-packages/django/core/handlers/exception.py", line 39, in inner
    response = get_response(request)
  File "/home/ieee/bnbserver/local/lib/python2.7/site-packages/django/core/handlers/base.py", line 187, in _get_response
    response = self.process_exception_by_middleware(e, request)
  File "/home/ieee/bnbserver/local/lib/python2.7/site-packages/django/core/handlers/base.py", line 185, in _get_response
    response = wrapped_callback(request, *callback_args, **callback_kwargs)
  File "/home/ieee/bnbserver/local/lib/python2.7/site-packages/django/contrib/auth/decorators.py", line 23, in _wrapped_view
    return view_func(request, *args, **kwargs)
  File "/home/ieee/bnbserver/bnb2017/fblogin/views.py", line 16, in home
    'fbid': SocialAccount.objects.get(user=request.user).uid,
  File "/home/ieee/bnbserver/local/lib/python2.7/site-packages/django/db/models/manager.py", line 85, in manager_method
    return getattr(self.get_queryset(), name)(*args, **kwargs)
  File "/home/ieee/bnbserver/local/lib/python2.7/site-packages/django/db/models/query.py", line 385, in get
    self.model._meta.object_name
DoesNotExist: SocialAccount matching query does not exist.
Internal Server Error: /favicon.ico
Traceback (most recent call last):
  File "/home/ieee/bnbserver/local/lib/python2.7/site-packages/django/core/handlers/exception.py", line 39, in inner
    response = get_response(request)
  File "/home/ieee/bnbserver/local/lib/python2.7/site-packages/django/core/handlers/base.py", line 187, in _get_response
    response = self.process_exception_by_middleware(e, request)
  File "/home/ieee/bnbserver/local/lib/python2.7/site-packages/django/core/handlers/base.py", line 185, in _get_response
    response = wrapped_callback(request, *callback_args, **callback_kwargs)
  File "/home/ieee/bnbserver/local/lib/python2.7/site-packages/django/contrib/auth/decorators.py", line 23, in _wrapped_view
    return view_func(request, *args, **kwargs)
  File "/home/ieee/bnbserver/bnb2017/fblogin/views.py", line 16, in home
    'fbid': SocialAccount.objects.get(user=request.user).uid,
  File "/home/ieee/bnbserver/local/lib/python2.7/site-packages/django/db/models/manager.py", line 85, in manager_method
    return getattr(self.get_queryset(), name)(*args, **kwargs)
  File "/home/ieee/bnbserver/local/lib/python2.7/site-packages/django/db/models/query.py", line 385, in get
    self.model._meta.object_name
DoesNotExist: SocialAccount matching query does not exist.
Internal Server Error: /favicon.ico
Traceback (most recent call last):
  File "/home/ieee/bnbserver/local/lib/python2.7/site-packages/django/core/handlers/exception.py", line 39, in inner
    response = get_response(request)
  File "/home/ieee/bnbserver/local/lib/python2.7/site-packages/django/core/handlers/base.py", line 187, in _get_response
    response = self.process_exception_by_middleware(e, request)
  File "/home/ieee/bnbserver/local/lib/python2.7/site-packages/django/core/handlers/base.py", line 185, in _get_response
    response = wrapped_callback(request, *callback_args, **callback_kwargs)
  File "/home/ieee/bnbserver/local/lib/python2.7/site-packages/django/contrib/auth/decorators.py", line 23, in _wrapped_view
    return view_func(request, *args, **kwargs)
  File "/home/ieee/bnbserver/bnb2017/fblogin/views.py", line 16, in home
    'fbid': SocialAccount.objects.get(user=request.user).uid,
  File "/home/ieee/bnbserver/local/lib/python2.7/site-packages/django/db/models/manager.py", line 85, in manager_method
    return getattr(self.get_queryset(), name)(*args, **kwargs)
  File "/home/ieee/bnbserver/local/lib/python2.7/site-packages/django/db/models/query.py", line 385, in get
    self.model._meta.object_name
DoesNotExist: SocialAccount matching query does not exist.
Internal Server Error: /favicon.ico
Traceback (most recent call last):
  File "/home/ieee/bnbserver/local/lib/python2.7/site-packages/django/core/handlers/exception.py", line 39, in inner
    response = get_response(request)
  File "/home/ieee/bnbserver/local/lib/python2.7/site-packages/django/core/handlers/base.py", line 187, in _get_response
    response = self.process_exception_by_middleware(e, request)
  File "/home/ieee/bnbserver/local/lib/python2.7/site-packages/django/core/handlers/base.py", line 185, in _get_response
    response = wrapped_callback(request, *callback_args, **callback_kwargs)
  File "/home/ieee/bnbserver/local/lib/python2.7/site-packages/django/contrib/auth/decorators.py", line 23, in _wrapped_view
    return view_func(request, *args, **kwargs)
  File "/home/ieee/bnbserver/bnb2017/fblogin/views.py", line 16, in home
    'fbid': SocialAccount.objects.get(user=request.user).uid,
  File "/home/ieee/bnbserver/local/lib/python2.7/site-packages/django/db/models/manager.py", line 85, in manager_method
    return getattr(self.get_queryset(), name)(*args, **kwargs)
  File "/home/ieee/bnbserver/local/lib/python2.7/site-packages/django/db/models/query.py", line 385, in get
    self.model._meta.object_name
DoesNotExist: SocialAccount matching query does not exist.
Internal Server Error: /favicon.ico
Traceback (most recent call last):
  File "/home/ieee/bnbserver/local/lib/python2.7/site-packages/django/core/handlers/exception.py", line 39, in inner
    response = get_response(request)
  File "/home/ieee/bnbserver/local/lib/python2.7/site-packages/django/core/handlers/base.py", line 187, in _get_response
    response = self.process_exception_by_middleware(e, request)
  File "/home/ieee/bnbserver/local/lib/python2.7/site-packages/django/core/handlers/base.py", line 185, in _get_response
    response = wrapped_callback(request, *callback_args, **callback_kwargs)
  File "/home/ieee/bnbserver/local/lib/python2.7/site-packages/django/contrib/auth/decorators.py", line 23, in _wrapped_view
    return view_func(request, *args, **kwargs)
  File "/home/ieee/bnbserver/bnb2017/fblogin/views.py", line 16, in home
    'fbid': SocialAccount.objects.get(user=request.user).uid,
  File "/home/ieee/bnbserver/local/lib/python2.7/site-packages/django/db/models/manager.py", line 85, in manager_method
    return getattr(self.get_queryset(), name)(*args, **kwargs)
  File "/home/ieee/bnbserver/local/lib/python2.7/site-packages/django/db/models/query.py", line 385, in get
    self.model._meta.object_name
DoesNotExist: SocialAccount matching query does not exist.
Internal Server Error: /favicon.ico
Traceback (most recent call last):
  File "/home/ieee/bnbserver/local/lib/python2.7/site-packages/django/core/handlers/exception.py", line 39, in inner
    response = get_response(request)
  File "/home/ieee/bnbserver/local/lib/python2.7/site-packages/django/core/handlers/base.py", line 187, in _get_response
    response = self.process_exception_by_middleware(e, request)
  File "/home/ieee/bnbserver/local/lib/python2.7/site-packages/django/core/handlers/base.py", line 185, in _get_response
    response = wrapped_callback(request, *callback_args, **callback_kwargs)
  File "/home/ieee/bnbserver/local/lib/python2.7/site-packages/django/contrib/auth/decorators.py", line 23, in _wrapped_view
    return view_func(request, *args, **kwargs)
  File "/home/ieee/bnbserver/bnb2017/fblogin/views.py", line 16, in home
    'fbid': SocialAccount.objects.get(user=request.user).uid,
  File "/home/ieee/bnbserver/local/lib/python2.7/site-packages/django/db/models/manager.py", line 85, in manager_method
    return getattr(self.get_queryset(), name)(*args, **kwargs)
  File "/home/ieee/bnbserver/local/lib/python2.7/site-packages/django/db/models/query.py", line 385, in get
    self.model._meta.object_name
DoesNotExist: SocialAccount matching query does not exist.
Internal Server Error: /favicon.ico
Traceback (most recent call last):
  File "/home/ieee/bnbserver/local/lib/python2.7/site-packages/django/core/handlers/exception.py", line 39, in inner
    response = get_response(request)
  File "/home/ieee/bnbserver/local/lib/python2.7/site-packages/django/core/handlers/base.py", line 187, in _get_response
    response = self.process_exception_by_middleware(e, request)
  File "/home/ieee/bnbserver/local/lib/python2.7/site-packages/django/core/handlers/base.py", line 185, in _get_response
    response = wrapped_callback(request, *callback_args, **callback_kwargs)
  File "/home/ieee/bnbserver/local/lib/python2.7/site-packages/django/contrib/auth/decorators.py", line 23, in _wrapped_view
    return view_func(request, *args, **kwargs)
  File "/home/ieee/bnbserver/bnb2017/fblogin/views.py", line 16, in home
    'fbid': SocialAccount.objects.get(user=request.user).uid,
  File "/home/ieee/bnbserver/local/lib/python2.7/site-packages/django/db/models/manager.py", line 85, in manager_method
    return getattr(self.get_queryset(), name)(*args, **kwargs)
  File "/home/ieee/bnbserver/local/lib/python2.7/site-packages/django/db/models/query.py", line 385, in get
    self.model._meta.object_name
DoesNotExist: SocialAccount matching query does not exist.
Internal Server Error: /favicon.ico
Traceback (most recent call last):
  File "/home/ieee/bnbserver/local/lib/python2.7/site-packages/django/core/handlers/exception.py", line 39, in inner
    response = get_response(request)
  File "/home/ieee/bnbserver/local/lib/python2.7/site-packages/django/core/handlers/base.py", line 187, in _get_response
    response = self.process_exception_by_middleware(e, request)
  File "/home/ieee/bnbserver/local/lib/python2.7/site-packages/django/core/handlers/base.py", line 185, in _get_response
    response = wrapped_callback(request, *callback_args, **callback_kwargs)
  File "/home/ieee/bnbserver/local/lib/python2.7/site-packages/django/contrib/auth/decorators.py", line 23, in _wrapped_view
    return view_func(request, *args, **kwargs)
  File "/home/ieee/bnbserver/bnb2017/fblogin/views.py", line 16, in home
    'fbid': SocialAccount.objects.get(user=request.user).uid,
  File "/home/ieee/bnbserver/local/lib/python2.7/site-packages/django/db/models/manager.py", line 85, in manager_method
    return getattr(self.get_queryset(), name)(*args, **kwargs)
  File "/home/ieee/bnbserver/local/lib/python2.7/site-packages/django/db/models/query.py", line 385, in get
    self.model._meta.object_name
DoesNotExist: SocialAccount matching query does not exist.
Internal Server Error: /favicon.ico
Traceback (most recent call last):
  File "/home/ieee/bnbserver/local/lib/python2.7/site-packages/django/core/handlers/exception.py", line 39, in inner
    response = get_response(request)
  File "/home/ieee/bnbserver/local/lib/python2.7/site-packages/django/core/handlers/base.py", line 187, in _get_response
    response = self.process_exception_by_middleware(e, request)
  File "/home/ieee/bnbserver/local/lib/python2.7/site-packages/django/core/handlers/base.py", line 185, in _get_response
    response = wrapped_callback(request, *callback_args, **callback_kwargs)
  File "/home/ieee/bnbserver/local/lib/python2.7/site-packages/django/contrib/auth/decorators.py", line 23, in _wrapped_view
    return view_func(request, *args, **kwargs)
  File "/home/ieee/bnbserver/bnb2017/fblogin/views.py", line 16, in home
    'fbid': SocialAccount.objects.get(user=request.user).uid,
  File "/home/ieee/bnbserver/local/lib/python2.7/site-packages/django/db/models/manager.py", line 85, in manager_method
    return getattr(self.get_queryset(), name)(*args, **kwargs)
  File "/home/ieee/bnbserver/local/lib/python2.7/site-packages/django/db/models/query.py", line 385, in get
    self.model._meta.object_name
DoesNotExist: SocialAccount matching query does not exist.
Internal Server Error: /favicon.ico
Traceback (most recent call last):
  File "/home/ieee/bnbserver/local/lib/python2.7/site-packages/django/core/handlers/exception.py", line 39, in inner
    response = get_response(request)
  File "/home/ieee/bnbserver/local/lib/python2.7/site-packages/django/core/handlers/base.py", line 187, in _get_response
    response = self.process_exception_by_middleware(e, request)
  File "/home/ieee/bnbserver/local/lib/python2.7/site-packages/django/core/handlers/base.py", line 185, in _get_response
    response = wrapped_callback(request, *callback_args, **callback_kwargs)
  File "/home/ieee/bnbserver/local/lib/python2.7/site-packages/django/contrib/auth/decorators.py", line 23, in _wrapped_view
    return view_func(request, *args, **kwargs)
  File "/home/ieee/bnbserver/bnb2017/fblogin/views.py", line 16, in home
    'fbid': SocialAccount.objects.get(user=request.user).uid,
  File "/home/ieee/bnbserver/local/lib/python2.7/site-packages/django/db/models/manager.py", line 85, in manager_method
    return getattr(self.get_queryset(), name)(*args, **kwargs)
  File "/home/ieee/bnbserver/local/lib/python2.7/site-packages/django/db/models/query.py", line 385, in get
    self.model._meta.object_name
DoesNotExist: SocialAccount matching query does not exist.
Internal Server Error: /favicon.ico
Traceback (most recent call last):
  File "/home/ieee/bnbserver/local/lib/python2.7/site-packages/django/core/handlers/exception.py", line 39, in inner
    response = get_response(request)
  File "/home/ieee/bnbserver/local/lib/python2.7/site-packages/django/core/handlers/base.py", line 187, in _get_response
    response = self.process_exception_by_middleware(e, request)
  File "/home/ieee/bnbserver/local/lib/python2.7/site-packages/django/core/handlers/base.py", line 185, in _get_response
    response = wrapped_callback(request, *callback_args, **callback_kwargs)
  File "/home/ieee/bnbserver/local/lib/python2.7/site-packages/django/contrib/auth/decorators.py", line 23, in _wrapped_view
    return view_func(request, *args, **kwargs)
  File "/home/ieee/bnbserver/bnb2017/fblogin/views.py", line 16, in home
    'fbid': SocialAccount.objects.get(user=request.user).uid,
  File "/home/ieee/bnbserver/local/lib/python2.7/site-packages/django/db/models/manager.py", line 85, in manager_method
    return getattr(self.get_queryset(), name)(*args, **kwargs)
  File "/home/ieee/bnbserver/local/lib/python2.7/site-packages/django/db/models/query.py", line 385, in get
    self.model._meta.object_name
DoesNotExist: SocialAccount matching query does not exist.
Internal Server Error: /favicon.ico
Traceback (most recent call last):
  File "/home/ieee/bnbserver/local/lib/python2.7/site-packages/django/core/handlers/exception.py", line 39, in inner
    response = get_response(request)
  File "/home/ieee/bnbserver/local/lib/python2.7/site-packages/django/core/handlers/base.py", line 187, in _get_response
    response = self.process_exception_by_middleware(e, request)
  File "/home/ieee/bnbserver/local/lib/python2.7/site-packages/django/core/handlers/base.py", line 185, in _get_response
    response = wrapped_callback(request, *callback_args, **callback_kwargs)
  File "/home/ieee/bnbserver/local/lib/python2.7/site-packages/django/contrib/auth/decorators.py", line 23, in _wrapped_view
    return view_func(request, *args, **kwargs)
  File "/home/ieee/bnbserver/bnb2017/fblogin/views.py", line 16, in home
    'fbid': SocialAccount.objects.get(user=request.user).uid,
  File "/home/ieee/bnbserver/local/lib/python2.7/site-packages/django/db/models/manager.py", line 85, in manager_method
    return getattr(self.get_queryset(), name)(*args, **kwargs)
  File "/home/ieee/bnbserver/local/lib/python2.7/site-packages/django/db/models/query.py", line 385, in get
    self.model._meta.object_name
DoesNotExist: SocialAccount matching query does not exist.
Internal Server Error: /favicon.ico
Traceback (most recent call last):
  File "/home/ieee/bnbserver/local/lib/python2.7/site-packages/django/core/handlers/exception.py", line 39, in inner
    response = get_response(request)
  File "/home/ieee/bnbserver/local/lib/python2.7/site-packages/django/core/handlers/base.py", line 187, in _get_response
    response = self.process_exception_by_middleware(e, request)
  File "/home/ieee/bnbserver/local/lib/python2.7/site-packages/django/core/handlers/base.py", line 185, in _get_response
    response = wrapped_callback(request, *callback_args, **callback_kwargs)
  File "/home/ieee/bnbserver/local/lib/python2.7/site-packages/django/contrib/auth/decorators.py", line 23, in _wrapped_view
    return view_func(request, *args, **kwargs)
  File "/home/ieee/bnbserver/bnb2017/fblogin/views.py", line 16, in home
    'fbid': SocialAccount.objects.get(user=request.user).uid,
  File "/home/ieee/bnbserver/local/lib/python2.7/site-packages/django/db/models/manager.py", line 85, in manager_method
    return getattr(self.get_queryset(), name)(*args, **kwargs)
  File "/home/ieee/bnbserver/local/lib/python2.7/site-packages/django/db/models/query.py", line 385, in get
    self.model._meta.object_name
DoesNotExist: SocialAccount matching query does not exist.
Internal Server Error: /favicon.ico
Traceback (most recent call last):
  File "/home/ieee/bnbserver/local/lib/python2.7/site-packages/django/core/handlers/exception.py", line 39, in inner
    response = get_response(request)
  File "/home/ieee/bnbserver/local/lib/python2.7/site-packages/django/core/handlers/base.py", line 187, in _get_response
    response = self.process_exception_by_middleware(e, request)
  File "/home/ieee/bnbserver/local/lib/python2.7/site-packages/django/core/handlers/base.py", line 185, in _get_response
    response = wrapped_callback(request, *callback_args, **callback_kwargs)
  File "/home/ieee/bnbserver/local/lib/python2.7/site-packages/django/contrib/auth/decorators.py", line 23, in _wrapped_view
    return view_func(request, *args, **kwargs)
  File "/home/ieee/bnbserver/bnb2017/fblogin/views.py", line 16, in home
    'fbid': SocialAccount.objects.get(user=request.user).uid,
  File "/home/ieee/bnbserver/local/lib/python2.7/site-packages/django/db/models/manager.py", line 85, in manager_method
    return getattr(self.get_queryset(), name)(*args, **kwargs)
  File "/home/ieee/bnbserver/local/lib/python2.7/site-packages/django/db/models/query.py", line 385, in get
    self.model._meta.object_name
DoesNotExist: SocialAccount matching query does not exist.
Internal Server Error: /favicon.ico
Traceback (most recent call last):
  File "/home/ieee/bnbserver/local/lib/python2.7/site-packages/django/core/handlers/exception.py", line 39, in inner
    response = get_response(request)
  File "/home/ieee/bnbserver/local/lib/python2.7/site-packages/django/core/handlers/base.py", line 187, in _get_response
    response = self.process_exception_by_middleware(e, request)
  File "/home/ieee/bnbserver/local/lib/python2.7/site-packages/django/core/handlers/base.py", line 185, in _get_response
    response = wrapped_callback(request, *callback_args, **callback_kwargs)
  File "/home/ieee/bnbserver/local/lib/python2.7/site-packages/django/contrib/auth/decorators.py", line 23, in _wrapped_view
    return view_func(request, *args, **kwargs)
  File "/home/ieee/bnbserver/bnb2017/fblogin/views.py", line 16, in home
    'fbid': SocialAccount.objects.get(user=request.user).uid,
  File "/home/ieee/bnbserver/local/lib/python2.7/site-packages/django/db/models/manager.py", line 85, in manager_method
    return getattr(self.get_queryset(), name)(*args, **kwargs)
  File "/home/ieee/bnbserver/local/lib/python2.7/site-packages/django/db/models/query.py", line 385, in get
    self.model._meta.object_name
DoesNotExist: SocialAccount matching query does not exist.
Internal Server Error: /favicon.ico
Traceback (most recent call last):
  File "/home/ieee/bnbserver/local/lib/python2.7/site-packages/django/core/handlers/exception.py", line 39, in inner
    response = get_response(request)
  File "/home/ieee/bnbserver/local/lib/python2.7/site-packages/django/core/handlers/base.py", line 187, in _get_response
    response = self.process_exception_by_middleware(e, request)
  File "/home/ieee/bnbserver/local/lib/python2.7/site-packages/django/core/handlers/base.py", line 185, in _get_response
    response = wrapped_callback(request, *callback_args, **callback_kwargs)
  File "/home/ieee/bnbserver/local/lib/python2.7/site-packages/django/contrib/auth/decorators.py", line 23, in _wrapped_view
    return view_func(request, *args, **kwargs)
  File "/home/ieee/bnbserver/bnb2017/fblogin/views.py", line 16, in home
    'fbid': SocialAccount.objects.get(user=request.user).uid,
  File "/home/ieee/bnbserver/local/lib/python2.7/site-packages/django/db/models/manager.py", line 85, in manager_method
    return getattr(self.get_queryset(), name)(*args, **kwargs)
  File "/home/ieee/bnbserver/local/lib/python2.7/site-packages/django/db/models/query.py", line 385, in get
    self.model._meta.object_name
DoesNotExist: SocialAccount matching query does not exist.
Internal Server Error: /favicon.ico
Traceback (most recent call last):
  File "/home/ieee/bnbserver/local/lib/python2.7/site-packages/django/core/handlers/exception.py", line 39, in inner
    response = get_response(request)
  File "/home/ieee/bnbserver/local/lib/python2.7/site-packages/django/core/handlers/base.py", line 187, in _get_response
    response = self.process_exception_by_middleware(e, request)
  File "/home/ieee/bnbserver/local/lib/python2.7/site-packages/django/core/handlers/base.py", line 185, in _get_response
    response = wrapped_callback(request, *callback_args, **callback_kwargs)
  File "/home/ieee/bnbserver/local/lib/python2.7/site-packages/django/contrib/auth/decorators.py", line 23, in _wrapped_view
    return view_func(request, *args, **kwargs)
  File "/home/ieee/bnbserver/bnb2017/fblogin/views.py", line 16, in home
    'fbid': SocialAccount.objects.get(user=request.user).uid,
  File "/home/ieee/bnbserver/local/lib/python2.7/site-packages/django/db/models/manager.py", line 85, in manager_method
    return getattr(self.get_queryset(), name)(*args, **kwargs)
  File "/home/ieee/bnbserver/local/lib/python2.7/site-packages/django/db/models/query.py", line 385, in get
    self.model._meta.object_name
DoesNotExist: SocialAccount matching query does not exist.
Internal Server Error: /favicon.ico
Traceback (most recent call last):
  File "/home/ieee/bnbserver/local/lib/python2.7/site-packages/django/core/handlers/exception.py", line 39, in inner
    response = get_response(request)
  File "/home/ieee/bnbserver/local/lib/python2.7/site-packages/django/core/handlers/base.py", line 187, in _get_response
    response = self.process_exception_by_middleware(e, request)
  File "/home/ieee/bnbserver/local/lib/python2.7/site-packages/django/core/handlers/base.py", line 185, in _get_response
    response = wrapped_callback(request, *callback_args, **callback_kwargs)
  File "/home/ieee/bnbserver/local/lib/python2.7/site-packages/django/contrib/auth/decorators.py", line 23, in _wrapped_view
    return view_func(request, *args, **kwargs)
  File "/home/ieee/bnbserver/bnb2017/fblogin/views.py", line 16, in home
    'fbid': SocialAccount.objects.get(user=request.user).uid,
  File "/home/ieee/bnbserver/local/lib/python2.7/site-packages/django/db/models/manager.py", line 85, in manager_method
    return getattr(self.get_queryset(), name)(*args, **kwargs)
  File "/home/ieee/bnbserver/local/lib/python2.7/site-packages/django/db/models/query.py", line 385, in get
    self.model._meta.object_name
DoesNotExist: SocialAccount matching query does not exist.
Internal Server Error: /favicon.ico
Traceback (most recent call last):
  File "/home/ieee/bnbserver/local/lib/python2.7/site-packages/django/core/handlers/exception.py", line 39, in inner
    response = get_response(request)
  File "/home/ieee/bnbserver/local/lib/python2.7/site-packages/django/core/handlers/base.py", line 187, in _get_response
    response = self.process_exception_by_middleware(e, request)
  File "/home/ieee/bnbserver/local/lib/python2.7/site-packages/django/core/handlers/base.py", line 185, in _get_response
    response = wrapped_callback(request, *callback_args, **callback_kwargs)
  File "/home/ieee/bnbserver/local/lib/python2.7/site-packages/django/contrib/auth/decorators.py", line 23, in _wrapped_view
    return view_func(request, *args, **kwargs)
  File "/home/ieee/bnbserver/bnb2017/fblogin/views.py", line 16, in home
    'fbid': SocialAccount.objects.get(user=request.user).uid,
  File "/home/ieee/bnbserver/local/lib/python2.7/site-packages/django/db/models/manager.py", line 85, in manager_method
    return getattr(self.get_queryset(), name)(*args, **kwargs)
  File "/home/ieee/bnbserver/local/lib/python2.7/site-packages/django/db/models/query.py", line 385, in get
    self.model._meta.object_name
DoesNotExist: SocialAccount matching query does not exist.
Internal Server Error: /favicon.ico
Traceback (most recent call last):
  File "/home/ieee/bnbserver/local/lib/python2.7/site-packages/django/core/handlers/exception.py", line 39, in inner
    response = get_response(request)
  File "/home/ieee/bnbserver/local/lib/python2.7/site-packages/django/core/handlers/base.py", line 187, in _get_response
    response = self.process_exception_by_middleware(e, request)
  File "/home/ieee/bnbserver/local/lib/python2.7/site-packages/django/core/handlers/base.py", line 185, in _get_response
    response = wrapped_callback(request, *callback_args, **callback_kwargs)
  File "/home/ieee/bnbserver/local/lib/python2.7/site-packages/django/contrib/auth/decorators.py", line 23, in _wrapped_view
    return view_func(request, *args, **kwargs)
  File "/home/ieee/bnbserver/bnb2017/fblogin/views.py", line 16, in home
    'fbid': SocialAccount.objects.get(user=request.user).uid,
  File "/home/ieee/bnbserver/local/lib/python2.7/site-packages/django/db/models/manager.py", line 85, in manager_method
    return getattr(self.get_queryset(), name)(*args, **kwargs)
  File "/home/ieee/bnbserver/local/lib/python2.7/site-packages/django/db/models/query.py", line 385, in get
    self.model._meta.object_name
DoesNotExist: SocialAccount matching query does not exist.
Internal Server Error: /favicon.ico
Traceback (most recent call last):
  File "/home/ieee/bnbserver/local/lib/python2.7/site-packages/django/core/handlers/exception.py", line 39, in inner
    response = get_response(request)
  File "/home/ieee/bnbserver/local/lib/python2.7/site-packages/django/core/handlers/base.py", line 187, in _get_response
    response = self.process_exception_by_middleware(e, request)
  File "/home/ieee/bnbserver/local/lib/python2.7/site-packages/django/core/handlers/base.py", line 185, in _get_response
    response = wrapped_callback(request, *callback_args, **callback_kwargs)
  File "/home/ieee/bnbserver/local/lib/python2.7/site-packages/django/contrib/auth/decorators.py", line 23, in _wrapped_view
    return view_func(request, *args, **kwargs)
  File "/home/ieee/bnbserver/bnb2017/fblogin/views.py", line 16, in home
    'fbid': SocialAccount.objects.get(user=request.user).uid,
  File "/home/ieee/bnbserver/local/lib/python2.7/site-packages/django/db/models/manager.py", line 85, in manager_method
    return getattr(self.get_queryset(), name)(*args, **kwargs)
  File "/home/ieee/bnbserver/local/lib/python2.7/site-packages/django/db/models/query.py", line 385, in get
    self.model._meta.object_name
DoesNotExist: SocialAccount matching query does not exist.
Internal Server Error: /favicon.ico
Traceback (most recent call last):
  File "/home/ieee/bnbserver/local/lib/python2.7/site-packages/django/core/handlers/exception.py", line 39, in inner
    response = get_response(request)
  File "/home/ieee/bnbserver/local/lib/python2.7/site-packages/django/core/handlers/base.py", line 187, in _get_response
    response = self.process_exception_by_middleware(e, request)
  File "/home/ieee/bnbserver/local/lib/python2.7/site-packages/django/core/handlers/base.py", line 185, in _get_response
    response = wrapped_callback(request, *callback_args, **callback_kwargs)
  File "/home/ieee/bnbserver/local/lib/python2.7/site-packages/django/contrib/auth/decorators.py", line 23, in _wrapped_view
    return view_func(request, *args, **kwargs)
  File "/home/ieee/bnbserver/bnb2017/fblogin/views.py", line 16, in home
    'fbid': SocialAccount.objects.get(user=request.user).uid,
  File "/home/ieee/bnbserver/local/lib/python2.7/site-packages/django/db/models/manager.py", line 85, in manager_method
    return getattr(self.get_queryset(), name)(*args, **kwargs)
  File "/home/ieee/bnbserver/local/lib/python2.7/site-packages/django/db/models/query.py", line 385, in get
    self.model._meta.object_name
DoesNotExist: SocialAccount matching query does not exist.
Internal Server Error: /favicon.ico
Traceback (most recent call last):
  File "/home/ieee/bnbserver/local/lib/python2.7/site-packages/django/core/handlers/exception.py", line 39, in inner
    response = get_response(request)
  File "/home/ieee/bnbserver/local/lib/python2.7/site-packages/django/core/handlers/base.py", line 187, in _get_response
    response = self.process_exception_by_middleware(e, request)
  File "/home/ieee/bnbserver/local/lib/python2.7/site-packages/django/core/handlers/base.py", line 185, in _get_response
    response = wrapped_callback(request, *callback_args, **callback_kwargs)
  File "/home/ieee/bnbserver/local/lib/python2.7/site-packages/django/contrib/auth/decorators.py", line 23, in _wrapped_view
    return view_func(request, *args, **kwargs)
  File "/home/ieee/bnbserver/bnb2017/fblogin/views.py", line 16, in home
    'fbid': SocialAccount.objects.get(user=request.user).uid,
  File "/home/ieee/bnbserver/local/lib/python2.7/site-packages/django/db/models/manager.py", line 85, in manager_method
    return getattr(self.get_queryset(), name)(*args, **kwargs)
  File "/home/ieee/bnbserver/local/lib/python2.7/site-packages/django/db/models/query.py", line 385, in get
    self.model._meta.object_name
DoesNotExist: SocialAccount matching query does not exist.
Internal Server Error: /favicon.ico
Traceback (most recent call last):
  File "/home/ieee/bnbserver/local/lib/python2.7/site-packages/django/core/handlers/exception.py", line 39, in inner
    response = get_response(request)
  File "/home/ieee/bnbserver/local/lib/python2.7/site-packages/django/core/handlers/base.py", line 187, in _get_response
    response = self.process_exception_by_middleware(e, request)
  File "/home/ieee/bnbserver/local/lib/python2.7/site-packages/django/core/handlers/base.py", line 185, in _get_response
    response = wrapped_callback(request, *callback_args, **callback_kwargs)
  File "/home/ieee/bnbserver/local/lib/python2.7/site-packages/django/contrib/auth/decorators.py", line 23, in _wrapped_view
    return view_func(request, *args, **kwargs)
  File "/home/ieee/bnbserver/bnb2017/fblogin/views.py", line 16, in home
    'fbid': SocialAccount.objects.get(user=request.user).uid,
  File "/home/ieee/bnbserver/local/lib/python2.7/site-packages/django/db/models/manager.py", line 85, in manager_method
    return getattr(self.get_queryset(), name)(*args, **kwargs)
  File "/home/ieee/bnbserver/local/lib/python2.7/site-packages/django/db/models/query.py", line 385, in get
    self.model._meta.object_name
DoesNotExist: SocialAccount matching query does not exist.
Internal Server Error: /favicon.ico
Traceback (most recent call last):
  File "/home/ieee/bnbserver/local/lib/python2.7/site-packages/django/core/handlers/exception.py", line 39, in inner
    response = get_response(request)
  File "/home/ieee/bnbserver/local/lib/python2.7/site-packages/django/core/handlers/base.py", line 187, in _get_response
    response = self.process_exception_by_middleware(e, request)
  File "/home/ieee/bnbserver/local/lib/python2.7/site-packages/django/core/handlers/base.py", line 185, in _get_response
    response = wrapped_callback(request, *callback_args, **callback_kwargs)
  File "/home/ieee/bnbserver/local/lib/python2.7/site-packages/django/contrib/auth/decorators.py", line 23, in _wrapped_view
    return view_func(request, *args, **kwargs)
  File "/home/ieee/bnbserver/bnb2017/fblogin/views.py", line 16, in home
    'fbid': SocialAccount.objects.get(user=request.user).uid,
  File "/home/ieee/bnbserver/local/lib/python2.7/site-packages/django/db/models/manager.py", line 85, in manager_method
    return getattr(self.get_queryset(), name)(*args, **kwargs)
  File "/home/ieee/bnbserver/local/lib/python2.7/site-packages/django/db/models/query.py", line 385, in get
    self.model._meta.object_name
DoesNotExist: SocialAccount matching query does not exist.
Internal Server Error: /favicon.ico
Traceback (most recent call last):
  File "/home/ieee/bnbserver/local/lib/python2.7/site-packages/django/core/handlers/exception.py", line 39, in inner
    response = get_response(request)
  File "/home/ieee/bnbserver/local/lib/python2.7/site-packages/django/core/handlers/base.py", line 187, in _get_response
    response = self.process_exception_by_middleware(e, request)
  File "/home/ieee/bnbserver/local/lib/python2.7/site-packages/django/core/handlers/base.py", line 185, in _get_response
    response = wrapped_callback(request, *callback_args, **callback_kwargs)
  File "/home/ieee/bnbserver/local/lib/python2.7/site-packages/django/contrib/auth/decorators.py", line 23, in _wrapped_view
    return view_func(request, *args, **kwargs)
  File "/home/ieee/bnbserver/bnb2017/fblogin/views.py", line 16, in home
    'fbid': SocialAccount.objects.get(user=request.user).uid,
  File "/home/ieee/bnbserver/local/lib/python2.7/site-packages/django/db/models/manager.py", line 85, in manager_method
    return getattr(self.get_queryset(), name)(*args, **kwargs)
  File "/home/ieee/bnbserver/local/lib/python2.7/site-packages/django/db/models/query.py", line 385, in get
    self.model._meta.object_name
DoesNotExist: SocialAccount matching query does not exist.
Internal Server Error: /favicon.ico
Traceback (most recent call last):
  File "/home/ieee/bnbserver/local/lib/python2.7/site-packages/django/core/handlers/exception.py", line 39, in inner
    response = get_response(request)
  File "/home/ieee/bnbserver/local/lib/python2.7/site-packages/django/core/handlers/base.py", line 187, in _get_response
    response = self.process_exception_by_middleware(e, request)
  File "/home/ieee/bnbserver/local/lib/python2.7/site-packages/django/core/handlers/base.py", line 185, in _get_response
    response = wrapped_callback(request, *callback_args, **callback_kwargs)
  File "/home/ieee/bnbserver/local/lib/python2.7/site-packages/django/contrib/auth/decorators.py", line 23, in _wrapped_view
    return view_func(request, *args, **kwargs)
  File "/home/ieee/bnbserver/bnb2017/fblogin/views.py", line 16, in home
    'fbid': SocialAccount.objects.get(user=request.user).uid,
  File "/home/ieee/bnbserver/local/lib/python2.7/site-packages/django/db/models/manager.py", line 85, in manager_method
    return getattr(self.get_queryset(), name)(*args, **kwargs)
  File "/home/ieee/bnbserver/local/lib/python2.7/site-packages/django/db/models/query.py", line 385, in get
    self.model._meta.object_name
DoesNotExist: SocialAccount matching query does not exist.
Internal Server Error: /favicon.ico
Traceback (most recent call last):
  File "/home/ieee/bnbserver/local/lib/python2.7/site-packages/django/core/handlers/exception.py", line 39, in inner
    response = get_response(request)
  File "/home/ieee/bnbserver/local/lib/python2.7/site-packages/django/core/handlers/base.py", line 187, in _get_response
    response = self.process_exception_by_middleware(e, request)
  File "/home/ieee/bnbserver/local/lib/python2.7/site-packages/django/core/handlers/base.py", line 185, in _get_response
    response = wrapped_callback(request, *callback_args, **callback_kwargs)
  File "/home/ieee/bnbserver/local/lib/python2.7/site-packages/django/contrib/auth/decorators.py", line 23, in _wrapped_view
    return view_func(request, *args, **kwargs)
  File "/home/ieee/bnbserver/bnb2017/fblogin/views.py", line 16, in home
    'fbid': SocialAccount.objects.get(user=request.user).uid,
  File "/home/ieee/bnbserver/local/lib/python2.7/site-packages/django/db/models/manager.py", line 85, in manager_method
    return getattr(self.get_queryset(), name)(*args, **kwargs)
  File "/home/ieee/bnbserver/local/lib/python2.7/site-packages/django/db/models/query.py", line 385, in get
    self.model._meta.object_name
DoesNotExist: SocialAccount matching query does not exist.
Internal Server Error: /favicon.ico
Traceback (most recent call last):
  File "/home/ieee/bnbserver/local/lib/python2.7/site-packages/django/core/handlers/exception.py", line 39, in inner
    response = get_response(request)
  File "/home/ieee/bnbserver/local/lib/python2.7/site-packages/django/core/handlers/base.py", line 187, in _get_response
    response = self.process_exception_by_middleware(e, request)
  File "/home/ieee/bnbserver/local/lib/python2.7/site-packages/django/core/handlers/base.py", line 185, in _get_response
    response = wrapped_callback(request, *callback_args, **callback_kwargs)
  File "/home/ieee/bnbserver/local/lib/python2.7/site-packages/django/contrib/auth/decorators.py", line 23, in _wrapped_view
    return view_func(request, *args, **kwargs)
  File "/home/ieee/bnbserver/bnb2017/fblogin/views.py", line 16, in home
    'fbid': SocialAccount.objects.get(user=request.user).uid,
  File "/home/ieee/bnbserver/local/lib/python2.7/site-packages/django/db/models/manager.py", line 85, in manager_method
    return getattr(self.get_queryset(), name)(*args, **kwargs)
  File "/home/ieee/bnbserver/local/lib/python2.7/site-packages/django/db/models/query.py", line 385, in get
    self.model._meta.object_name
DoesNotExist: SocialAccount matching query does not exist.
Internal Server Error: /favicon.ico
Traceback (most recent call last):
  File "/home/ieee/bnbserver/local/lib/python2.7/site-packages/django/core/handlers/exception.py", line 39, in inner
    response = get_response(request)
  File "/home/ieee/bnbserver/local/lib/python2.7/site-packages/django/core/handlers/base.py", line 187, in _get_response
    response = self.process_exception_by_middleware(e, request)
  File "/home/ieee/bnbserver/local/lib/python2.7/site-packages/django/core/handlers/base.py", line 185, in _get_response
    response = wrapped_callback(request, *callback_args, **callback_kwargs)
  File "/home/ieee/bnbserver/local/lib/python2.7/site-packages/django/contrib/auth/decorators.py", line 23, in _wrapped_view
    return view_func(request, *args, **kwargs)
  File "/home/ieee/bnbserver/bnb2017/fblogin/views.py", line 16, in home
    'fbid': SocialAccount.objects.get(user=request.user).uid,
  File "/home/ieee/bnbserver/local/lib/python2.7/site-packages/django/db/models/manager.py", line 85, in manager_method
    return getattr(self.get_queryset(), name)(*args, **kwargs)
  File "/home/ieee/bnbserver/local/lib/python2.7/site-packages/django/db/models/query.py", line 385, in get
    self.model._meta.object_name
DoesNotExist: SocialAccount matching query does not exist.
Internal Server Error: /favicon.ico
Traceback (most recent call last):
  File "/home/ieee/bnbserver/local/lib/python2.7/site-packages/django/core/handlers/exception.py", line 39, in inner
    response = get_response(request)
  File "/home/ieee/bnbserver/local/lib/python2.7/site-packages/django/core/handlers/base.py", line 187, in _get_response
    response = self.process_exception_by_middleware(e, request)
  File "/home/ieee/bnbserver/local/lib/python2.7/site-packages/django/core/handlers/base.py", line 185, in _get_response
    response = wrapped_callback(request, *callback_args, **callback_kwargs)
  File "/home/ieee/bnbserver/local/lib/python2.7/site-packages/django/contrib/auth/decorators.py", line 23, in _wrapped_view
    return view_func(request, *args, **kwargs)
  File "/home/ieee/bnbserver/bnb2017/fblogin/views.py", line 16, in home
    'fbid': SocialAccount.objects.get(user=request.user).uid,
  File "/home/ieee/bnbserver/local/lib/python2.7/site-packages/django/db/models/manager.py", line 85, in manager_method
    return getattr(self.get_queryset(), name)(*args, **kwargs)
  File "/home/ieee/bnbserver/local/lib/python2.7/site-packages/django/db/models/query.py", line 385, in get
    self.model._meta.object_name
DoesNotExist: SocialAccount matching query does not exist.
Internal Server Error: /favicon.ico
Traceback (most recent call last):
  File "/home/ieee/bnbserver/local/lib/python2.7/site-packages/django/core/handlers/exception.py", line 39, in inner
    response = get_response(request)
  File "/home/ieee/bnbserver/local/lib/python2.7/site-packages/django/core/handlers/base.py", line 187, in _get_response
    response = self.process_exception_by_middleware(e, request)
  File "/home/ieee/bnbserver/local/lib/python2.7/site-packages/django/core/handlers/base.py", line 185, in _get_response
    response = wrapped_callback(request, *callback_args, **callback_kwargs)
  File "/home/ieee/bnbserver/local/lib/python2.7/site-packages/django/contrib/auth/decorators.py", line 23, in _wrapped_view
    return view_func(request, *args, **kwargs)
  File "/home/ieee/bnbserver/bnb2017/fblogin/views.py", line 16, in home
    'fbid': SocialAccount.objects.get(user=request.user).uid,
  File "/home/ieee/bnbserver/local/lib/python2.7/site-packages/django/db/models/manager.py", line 85, in manager_method
    return getattr(self.get_queryset(), name)(*args, **kwargs)
  File "/home/ieee/bnbserver/local/lib/python2.7/site-packages/django/db/models/query.py", line 385, in get
    self.model._meta.object_name
DoesNotExist: SocialAccount matching query does not exist.
Internal Server Error: /favicon.ico
Traceback (most recent call last):
  File "/home/ieee/bnbserver/local/lib/python2.7/site-packages/django/core/handlers/exception.py", line 39, in inner
    response = get_response(request)
  File "/home/ieee/bnbserver/local/lib/python2.7/site-packages/django/core/handlers/base.py", line 187, in _get_response
    response = self.process_exception_by_middleware(e, request)
  File "/home/ieee/bnbserver/local/lib/python2.7/site-packages/django/core/handlers/base.py", line 185, in _get_response
    response = wrapped_callback(request, *callback_args, **callback_kwargs)
  File "/home/ieee/bnbserver/local/lib/python2.7/site-packages/django/contrib/auth/decorators.py", line 23, in _wrapped_view
    return view_func(request, *args, **kwargs)
  File "/home/ieee/bnbserver/bnb2017/fblogin/views.py", line 16, in home
    'fbid': SocialAccount.objects.get(user=request.user).uid,
  File "/home/ieee/bnbserver/local/lib/python2.7/site-packages/django/db/models/manager.py", line 85, in manager_method
    return getattr(self.get_queryset(), name)(*args, **kwargs)
  File "/home/ieee/bnbserver/local/lib/python2.7/site-packages/django/db/models/query.py", line 385, in get
    self.model._meta.object_name
DoesNotExist: SocialAccount matching query does not exist.
Internal Server Error: /favicon.ico
Traceback (most recent call last):
  File "/home/ieee/bnbserver/local/lib/python2.7/site-packages/django/core/handlers/exception.py", line 39, in inner
    response = get_response(request)
  File "/home/ieee/bnbserver/local/lib/python2.7/site-packages/django/core/handlers/base.py", line 187, in _get_response
    response = self.process_exception_by_middleware(e, request)
  File "/home/ieee/bnbserver/local/lib/python2.7/site-packages/django/core/handlers/base.py", line 185, in _get_response
    response = wrapped_callback(request, *callback_args, **callback_kwargs)
  File "/home/ieee/bnbserver/local/lib/python2.7/site-packages/django/contrib/auth/decorators.py", line 23, in _wrapped_view
    return view_func(request, *args, **kwargs)
  File "/home/ieee/bnbserver/bnb2017/fblogin/views.py", line 16, in home
    'fbid': SocialAccount.objects.get(user=request.user).uid,
  File "/home/ieee/bnbserver/local/lib/python2.7/site-packages/django/db/models/manager.py", line 85, in manager_method
    return getattr(self.get_queryset(), name)(*args, **kwargs)
  File "/home/ieee/bnbserver/local/lib/python2.7/site-packages/django/db/models/query.py", line 385, in get
    self.model._meta.object_name
DoesNotExist: SocialAccount matching query does not exist.
Internal Server Error: /favicon.ico
Traceback (most recent call last):
  File "/home/ieee/bnbserver/local/lib/python2.7/site-packages/django/core/handlers/exception.py", line 39, in inner
    response = get_response(request)
  File "/home/ieee/bnbserver/local/lib/python2.7/site-packages/django/core/handlers/base.py", line 187, in _get_response
    response = self.process_exception_by_middleware(e, request)
  File "/home/ieee/bnbserver/local/lib/python2.7/site-packages/django/core/handlers/base.py", line 185, in _get_response
    response = wrapped_callback(request, *callback_args, **callback_kwargs)
  File "/home/ieee/bnbserver/local/lib/python2.7/site-packages/django/contrib/auth/decorators.py", line 23, in _wrapped_view
    return view_func(request, *args, **kwargs)
  File "/home/ieee/bnbserver/bnb2017/fblogin/views.py", line 16, in home
    'fbid': SocialAccount.objects.get(user=request.user).uid,
  File "/home/ieee/bnbserver/local/lib/python2.7/site-packages/django/db/models/manager.py", line 85, in manager_method
    return getattr(self.get_queryset(), name)(*args, **kwargs)
  File "/home/ieee/bnbserver/local/lib/python2.7/site-packages/django/db/models/query.py", line 385, in get
    self.model._meta.object_name
DoesNotExist: SocialAccount matching query does not exist.
Internal Server Error: /favicon.ico
Traceback (most recent call last):
  File "/home/ieee/bnbserver/local/lib/python2.7/site-packages/django/core/handlers/exception.py", line 39, in inner
    response = get_response(request)
  File "/home/ieee/bnbserver/local/lib/python2.7/site-packages/django/core/handlers/base.py", line 187, in _get_response
    response = self.process_exception_by_middleware(e, request)
  File "/home/ieee/bnbserver/local/lib/python2.7/site-packages/django/core/handlers/base.py", line 185, in _get_response
    response = wrapped_callback(request, *callback_args, **callback_kwargs)
  File "/home/ieee/bnbserver/local/lib/python2.7/site-packages/django/contrib/auth/decorators.py", line 23, in _wrapped_view
    return view_func(request, *args, **kwargs)
  File "/home/ieee/bnbserver/bnb2017/fblogin/views.py", line 16, in home
    'fbid': SocialAccount.objects.get(user=request.user).uid,
  File "/home/ieee/bnbserver/local/lib/python2.7/site-packages/django/db/models/manager.py", line 85, in manager_method
    return getattr(self.get_queryset(), name)(*args, **kwargs)
  File "/home/ieee/bnbserver/local/lib/python2.7/site-packages/django/db/models/query.py", line 385, in get
    self.model._meta.object_name
DoesNotExist: SocialAccount matching query does not exist.
